Workbook

Sheet Result
A1: keyword | B1: occurrences | C1: total link strength
A2: microbial fuel cell | B2: 151 | C2: 589
A3: bioelectrochemical system | B3: 28 | C3: 123
A4: wastewater treatment | B4: 17 | C4: 70
A5: extracellular electron transfer | B5: 14 | C5: 63
A6: biosensor | B6: 13 | C6: 58
A7: wastewater | B7: 12 | C7: 41
A8: biofilm | B8: 10 | C8: 37
A9: renewable energy | B9: 10 | C9: 43
A10: bioelectricity | B10: 9 | C10: 37 | D10: Energy generation
A11: bioenergy | B11: 9 | C11: 36 | D11: Energy generation
A12: power density | B12: 9 | C12: 37 | D12: Energy generation
A13: shewanella | B13: 9 | C13: 37 | D13: Bacteria (keyword/strains)
A14: electricity generation | B14: 8 | C14: 33 | D14: Energy generation
A15: geobacter | B15: 8 | C15: 42 | D15: Bacteria (keyword/strains)
A16: microbial electrolysis cell | B16: 8 | C16: 30 | D16: Synthesis/Catalysis
A17: biocatalysis | B17: 7 | C17: 28 | D17: Synthesis/Catalysis
A18: electrochemistry | B18: 7 | C18: 31 | D18: Analysis tools
A19: electrode | B19: 7 | C19: 29 | D19: System (Configuration/Application)
A20: electron transfer | B20: 7 | C20: 35 | D20: Mechanisms (Electron Transfer)
A21: remediation | B21: 6 | C21: 30 | D21: Environmental
... A25: exoelectrogen | B25: 6 | C25: 31 | D25: Mechanisms (Electron Transfer)
A26: resource recovery | B26: 5 | C26: 21 | D26: Environmental | E26: Sub-Categories | F26: Occurrences | G26: Keywords | H26: Percentage (Total)
A27: anaerobic digestion | B27: 5 | C27: 24 | D27: Synthesis/Catalysis | E27: Synthesis/Catalysis | F27: =SUMIF($D$2:$D$467,E27,$B$2:$B$467) -> 106 | G27: =COUNTIF(D:D,E27) -> 64 | H27: =F27/SUM($F$27:$F$39) -> 0.14002642
A28: ceramic membrane | B28: 5 | C28: 20 | D28: System (Materials/Fabrication) | E28: System (Materials/Fabrication) | F28: =SUMIF($D$2:$D$467,E28,$B$2:$B$467) -> 92 | G28: =COUNTIF(D:D,E28) -> 59 | H28: =F28/SUM($F$27:$F$39) -> 0.12153236
A29: electroactive biofilm | B29: 5 | C29: 22 | D29: Biofilm | E29: System (Configuration/Application) | F29: =SUMIF($D$2:$D$467,E29,$B$2:$B$467) -> 85 | G29: =COUNTIF(D:D,E29) -> 52 | H29: =F29/SUM($F$27:$F$39) -> 0.11228534
A30: escherichia coli | B30: 5 | C30: 18 | D30: Bacteria (keyword/strains) | E30: Energy generation | F30: =SUMIF($D$2:$D$467,E30,$B$2:$B$467) -> 74 | G30: =COUNTIF(D:D,E30) -> 32 | H30: =F30/SUM($F$27:$F$39) -> 0.097754293
A31: graphene | B31: 5 | C31: 22 | D31: System (Materials/Fabrication) | E31: Mechanisms (Electron Transfer) | F31: =SUMIF($D$2:$D$467,E31,$B$2:$B$467) -> 70 | G31: =COUNTIF(D:D,E31) -> 35 | H31: =F31/SUM($F$27:$F$39) -> 0.092470277
A32: nanotechnology | B32: 5 | C32: 21 | D32: System (Materials/Fabrication) | E32: Analysis tools | F32: =SUMIF($D$2:$D$467,E32,$B$2:$B$467) -> 52 | G32: =COUNTIF(D:D,E32) -> 33 | H32: =F32/SUM($F$27:$F$39) -> 0.068692206
A33: stack Configuration/Application | B33: 5 | C33: 24 | D33: System (Configuration/Application) | E33: Bacteria (keyword/strains) | F33: =SUMIF($D$2:$D$467,E33,$B$2:$B$467) -> 49 | G33: =COUNTIF(D:D,E33) -> 19 | H33: =F33/SUM($F$27:$F$39) -> 0.064729194
A34: urine | B34: 5 | C34: 23 | D34: Other | E34: Other microorganism | F34: =SUMIF($D$2:$D$467,E34,$B$2:$B$467) -> 42 | G34: =COUNTIF(D:D,E34) -> 22 | H34: =F34/SUM($F$27:$F$39) -> 0.055482166
A35: electron transport | B35: 5 | C35: 24 | D35: Mechanisms (Electron Transfer) | E35: Environmental | F35: =SUMIF($D$2:$D$467,E35,$B$2:$B$467) -> 36 | G35: =COUNTIF(D:D,E35) -> 21 | H35: =F35/SUM($F$27:$F$39) -> 0.047556143
A36: bacteria | B36: 4 | C36: 14 | D36: Bacteria (keyword/strains) | E36: Other Biomolecules | F36: =SUMIF($D$2:$D$467,E36,$B$2:$B$467) -> 19 | G36: =COUNTIF(D:D,E36) -> 11 | H36: =F36/SUM($F$27:$F$39) -> 0.025099075
A37: bioelectrocatalysis | B37: 4 | C37: 14 | D37: Synthesis/Catalysis | E37: Biofilm | F37: =SUMIF($D$2:$D$467,E37,$B$2:$B$467) -> 8 | G37: =COUNTIF(D:D,E37) -> 4 | H37: =F37/SUM($F$27:$F$39) -> 0.010568032
A38: bioelectrosynthesis | B38: 4 | C38: 22 | D38: Synthesis/Catalysis | E38: Other | F38: =SUMIF($D$2:$D$467,E38,$B$2:$B$467) -> 104 | G38: =COUNTIF(D:D,E38) -> 84 | H38: =F38/SUM($F$27:$F$39) -> 0.13738441
A39: cathode | B39: 4 | C39: 25 | D39: System (Configuration/Application) | E39: Unrelated | F39: =SUMIF($D$2:$D$467,E39,$B$2:$B$467) -> 20 | G39: =COUNTIF(D:D,E39) -> 19 | H39: =F39/SUM($F$27:$F$39) -> 0.026420079
A40: continuous flow | B40: 4 | C40: 18 | D40: Other | F40: =SUM(F27:F39) -> 757 | G40: =SUM(G27:G39) -> 455 | H40: =SUM(H27:H39) -> 1
A41: coulombic efficiency | B41: 4 | C41: 15 | D41: Analysis tools
A42: electroactive bacteria | B42: 4 | C42: 15 | D42: Bacteria (keyword/strains) | E42: Main | F42: =SUM(B2:B9) -> 255 | H42: =F42/SUM($F$42:$F$45) -> 0.25197628
A43: energy production | B43: 4 | C43: 16 | D43: Energy generation | E43: Sub | F43: =SUM(F27:F37) -> 633 | H43: =F43/SUM($F$42:$F$45) -> 0.62549407
...

Sheet Year by year keywords
A3: Count of KEYWORD | B3: Column Labels
A4: Row Labels | B4: 2013 | C4: 2014 | D4: 2015 | E4: 2016 | F4: 2017 | G4: 2018 | H4: Grand Total
A5: Analysis tools | B5: 6 | C5: 4 | D5: 6 | E5: 2 | F5: 8 | G5: 5 | H5: 31
A6: Bacteria (keyword/strains) | B6: 2 | C6: 4 | D6: 3 | E6: 3 | F6: 9 | G6: 4 | H6: 25
A7: bioelectrochemical system | B7: 1 | C7: 3 | D7: 4 | E7: 4 | F7: 4 | G7: 6 | H7: 22
A8: Biofilm | B8: 1 | C8: 1 | D8: 3 | E8: 1 | F8: 1 | G8: 2 | H8: 9
A9: biosensor | D9: 4 | E9: 2 | F9: 1 | G9: 2 | H9: 9
A10: Energy generation | B10: 3 | C10: 6 | D10: 7 | E10: 14 | F10: 11 | G10: 9 | H10: 50
A11: Environmental | C11: 2 | D11: 6 | E11: 4 | F11: 5 | G11: 8 | H11: 25
A12: extracellular electron transfer | C12: 1 | D12: 4 | E12: 1 | F12: 1 | G12: 3 | H12: 10
A13: Mechanisms (Electron Transfer) | B13: 5 | C13: 3 | D13: 10 | E13: 5 | F13: 18 | G13: 9 | H13: 50
A14: microbial fuel cell | B14: 9 | C14: 14 | D14: 17 | E14: 17 | F14: 24 | G14: 19 | H14: 100
A15: Other Biomolecules | B15: 2 | C15: 2 | D15: 3 | E15: 2 | F15: 2 | H15: 11
A16: Other microorganism | B16: 3 | C16: 3 | D16: 3 | E16: 5 | F16: 5 | G16: 7 | H16: 26
A17: renewable energy | B17: 2 | D17: 2 | F17: 1 | G17: 2 | H17: 7
A18: Synthesis/Catalysis | B18: 4 | C18: 18 | D18: 10 | E18: 10 | F18: 15 | G18: 6 | H18: 63
A19: System (Configuration/Application) | B19: 7 | C19: 5 | D19: 10 | E19: 10 | F19: 12 | G19: 17 | H19: 61
A20: System (Materials/Fabrication) | B20: 4 | C20: 6 | D20: 11 | E20: 6 | F20: 15 | G20: 12 | H20: 54
A21: wastewater | B21: 1 | D21: 1 | E21: 3 | F21: 1 | G21: 3 | H21: 9
A22: wastewater treatment | B22: 1 | C22: 2 | D22: 1 | E22: 3 | F22: 2 | G22: 1 | H22: 10
A23: Grand Total | B23: 51 | C23: 74 | D23: 105 | E23: 92 | F23: 135 | G23: 115 | H23: 572

Sheet Year by year keywords-Selected
A3: Count of KEYWORD | B3: Column Labels
A4: Row Labels | B4: 2013 | C4: 2014 | D4: 2015 | E4: 2016 | F4: 2017 | G4: 2018 | H4: Grand Total
A5: bioelectrochemical system | B5: 1 | C5: 3 | D5: 4 | E5: 4 | F5: 4 | G5: 6 | H5: 22
A6: biofilm | B6: 1 | D6: 1 | E6: 1 | G6: 2 | H6: 5
A7: biosensor | D7: 4 | E7: 2 | F7: 1 | G7: 2 | H7: 9
A8: extracellular electron transfer | C8: 1 | D8: 4 | E8: 1 | F8: 1 | G8: 3 | H8: 10
A9: microbial fuel cell | B9: 9 | C9: 14 | D9: 17 | E9: 17 | F9: 24 | G9: 19 | H9: 100
A10: renewable energy | B10: 2 | D10: 2 | F10: 1 | G10: 2 | H10: 7
A11: wastewater | B11: 1 | D11: 1 | E11: 3 | F11: 1 | G11: 3 | H11: 9
A12: wastewater treatment | B12: 1 | C12: 2 | D12: 1 | E12: 3 | F12: 2 | G12: 1 | H12: 10
A13: Grand Total | B13: 15 | C13: 20 | D13: 34 | E13: 31 | F13: 34 | G13: 38 | H13: 172

Sheet Publication type Vs Year
A3: Count of DT | B3: Column Labels
A4: Row Labels | B4: Article | C4: Article; Book Chapter | D4: Article; Proceedings Paper | E4: Editorial Material | F4: Editorial Material; Book Chapter | G4: Proceedings Paper | H4: Review | I4: Review; Book Chapter | J4: Grand Total
A5: 2009 | B5: 1 | D5: 1 | G5: 1 | J5: 3
A6: 2010 | B6: 4 | C6: 1 | D6: 1 | G6: 1 | H6: 8 | J6: 15
A7: 2011 | B7: 6 | C7: 2 | G7: 3 | H7: 2 | J7: 13
A8: 2012 | B8: 12 | C8: 7 | D8: 3 | H8: 7 | J8: 29
A9: 2013 | B9: 12 | D9: 3 | E9: 1 | H9: 4 | J9: 20
A10: 2014 | B10: 19 | C10: 1 | G10: 2 | H10: 5 | J10: 27
A11: 2015 | B11: 10 | C11: 3 | G11: 1 | H11: 14 | J11: 28
A12: 2016 | B12: 13 | C12: 3 | D12: 1 | E12: 2 | G12: 4 | H12: 7 | J12: 30
A13: 2017 | B13: 16 | C13: 1 | D13: 4 | G13: 1 | H13: 20 | I13: 1 | J13: 43
A14: 2018 | B14: 13 | C14: 7 | D14: 1 | E14: 1 | F14: 1 | G14: 1 | H14: 11 | I14: 1 | J14: 36
A15: 2019 | B15: 14 | C15: 8 | D15: 1 | E15: 1 | H15: 7 | J15: 31
A16: Grand Total | B16: 120 | C16: 33 | D16: 15 | E16: 5 | F16: 1 | G16: 14 | H16: 85 | I16: 2 | J16: 275

Sheet Bibliographic data
A1: PPR ID | B1: DOI | C1: PT | D1: AU | E1: BA | F1: BE | G1: GP | H1: AF | I1: BF | J1: CA | K1: TI | L1: SO | M1: SE | N1: BS | O1: LA | P1: DT | Q1: CT | R1: CY | S1: CL | T1: SP | U1: HO | V1: DE | W1: ID | X1: AB | Y1: C1 | Z1: RP | AA1: EM | AB1: RI | AC1: OI | AD1: FU | AE1: FX | AF1: CR | AG1: NR | AH1: TC | AI1: Z9 | AJ1: U1 | AK1: U2 | AL1: PU | AM1: PI | AN1: PA | AO1: SN | AP1: EI | AQ1: BN | AR1: J9 | AS1: JI | AT1: PD | AU1: PY | AV1: VL | AW1: IS | AX1: PN | AY1: SU | AZ1: SI | BA1: MA | BB1: BP | BC1: EP | BD1: AR | BE1: DI | BF1: D2 | BG1: EA | BH1: EY | BI1: PG | BJ1: WC | BK1: SC | BL1: GA | BM1: UT | BN1: PM | BO1: OA | BP1: HC | BQ1: HP | BR1: DA
A2: 1 | B2: 10.1098/rspb.1911.0073 | C2: J | D2: Potter, MC | H2: Potter, MC | K2: Electrical effects accompanying the decomposition of organic compounds | L2: PROCEEDINGS OF THE ROYAL SOCIETY OF LONDON SERIES B-CONTAINING PAPERS OF A BIOLOGICAL CHARACTER | O2: English | P2: Article | AF2: Haacke O., 1892, FLORA, V75; Klein B., 1898, BERICHTE DTSCH BOT G, V16; POTTER MC, 1910, DURHAM U PHIL SOC P, V3; WALLER AD, 1910, CALIFORNIAN LECT; WALLER AD, 1903, SIGNS LIFE | AG2: 5 | AH2: 333 | AI2: 362 | AJ2: 3 | AK2: 79 | AL2: ROYAL SOC LONDON | AM2: LONDON | AN2: 6 CARLTON HOUSE TERRACE, LONDON SW1Y 5AG, ENGLAND | AO2: 0950-1193 | AR2: P R SOC LOND B-CONTA | AT2: SEP | AU2: 1911 | AV2: 84 | AW2: 571 | BB2: 260 | BC2: 276 | BE2: 10.1098/rspb.1911.0073 | BI2: 17 | BJ2: Biology | BK2: Life Sciences & Biomedicine - Other Topics | BL2: V05PR | BM2: WOS:000200378700006 | BO2: Bronze | BR2: 43698
A3: 2 | B3: 10.1097/00010694-192004000-00001 | C3: J | D3: Gillespie, LJ | H3: Gillespie, LJ | K3: Reduction potentials of bacterial cultures and of water-logged soils | L3: SOIL SCIENCE | O3: English | P3: Article | AF3: Bancroft WD, 1892, Z PHYS CHEM, V10, P387; BOSE, 1901, Z PHYS CHEM, V38, P28; Cannon WA, 1917, SCIENCE, V45, P178, DOI 10.1126/science.45.1156.178; Cole R, 1914, J EXP MED, V20, P363, DOI 10.1084/jem.20.4.363; Ehrlich P., 1885, SAUERSTOFFBEDURFNIS; Forbes GS, 1917, J AM CHEM SOC, V39, P1140, DOI 10.1021/ja02251a005; Forbes GS, 1914, J AM CHEM SOC, V36, P2030, DOI 10.1021/ja02187a006; Frary FC, 1915, J AM CHEM SOC, V37, P2246, DOI 10.1021/ja02175a001; FRED EB, 1916, J AGR RES, V5, P1161; Fredenhagen C, 1902, Z ANORG CHEM, V29, P396, DOI 10.1002/zaac.19020290132; GARRETSEN FC, 1915, MEDED PROEFSTAT JAVA, V5, P317; Gillespie LJ, 1918, SOIL SCI, V6, P219, DOI 10.1097/00010694-191809000-00002; Harden A, 1915, BIOCHEM J, V9, P379, DOI 10.1042/bj0090379; Hildebrand JH, 1913, J AM CHEM SOC, V35, P847, DOI 10.1021/ja02196a001; HONING JA, 1917, B PROEFSTAT MEDAN, V8; Keyes FG, 1912, J BIOL CHEM, V13, P305; KUHR CAH, 1915, RCH SUIKERINDUS NED, V23, P501; Lewis GN, 1906, J AM CHEM SOC, V28, P158, DOI 10.1021/ja01968a003; Lewis GN, 1909, J AM CHEM SOC, V31, P355, DOI 10.1021/ja01933a005; Michaelis L, 1912, BIOCHEM Z, V46, P131; Michaelis L., 1914, WASSERSTOFFIONENKONZ; NEUMANN B, 1894, Z PHYS CHEM, V14, P193; OBERSTADT, 1913, Z HYG, V75, P1; OSTWALDLUTHER, 1910, PHYSIKOCHEMISCHE MES; PETERS R, 1898, Z PHYS CHEM, V26, P193; Potter MC, 1911, P R SOC LOND B-CONTA, V84, P260, DOI 10.1098/rspb.1911.0073; POTTER MC, 1912, P U DURHAM PHIL SOC, V4, P230; Rogers LA, 1914, J INFECT DIS, V14, P411, DOI 10.1093/infdis/14.3.411; RUSSEL, 1915, J AGRIC SCI, V7, P1; SCHREINER O, 1910, USDA BUR SOILS B, V73; SCHREINER O, 1914, USDA B, V108; SCHREINER O, 1909, USDA BUR SOILS B, V56; SKINNER JJ, 1914, USDG B, V42; STIEGLITZ J, 1912, ELEMENTS QUALITATIVE, V1; SULLIVAN MX, 1914, SCIENCE, V39, P958; SULLIVAN MX, 1911, J IND ENG CHEM, V3, P1; VANLAAR JJ, 1907, LEHRBUCH THEORETISCH; WELLS RC, 1914, US GEOL SURVEY B, V548; White WP, 1914, J AM CHEM SOC, V36, P2011, DOI 10.1021/ja02187a004; 1918, AGR J INDIA 1, V13, P148 | AG3: 40 | AH3: 58 | AI3: 61 | AJ3: 0 | AK3: 2 | AL3: LIPPINCOTT WILLIAMS & WILKINS | AM3: PHILADELPHIA | AN3: 530 WALNUT ST, PHILADELPHIA, PA 19106-3621 USA | AO3: 0038-075X | AR3: SOIL SCI | AS3: Soil Sci. | AT3: APR | AU3: 1920 | AV3: 9 | AW3: 4 | BB3: 199 | BC3: 216 | BE3: 10.1097/00010694-192004000-00001 | BI3: 18 | BJ3: Soil Science | BK3: Agriculture | BL3: V5871 | BM3: WOS:000187706700001 | BR3: 43703
A4: 3 | B4: 10.1021/ja01395a001 | C4: J | D4: Davis, CE; Davidson, GM | H4: Davis, CE; Davidson, GM | K4: Studies of hydrogen ion concentration measurements. I. Methods of measurements | L4: JOURNAL OF THE AMERICAN CHEMICAL SOCIETY | O4: English | P4: Article | Y4: Natl Biscuit Co, Res Lab, New York, NY USA | AF4: BEANS, 1920, J AM CHEM SOC, V42, P2116; CARHART, 1900, ELECT MEASUREMENTS, P188; DAVIS, 1923, IND ENG CHEM, V15, P182; MELLOR FW, 1919, HIGHER MATH STUDENTS; Potter MC, 1911, P R SOC LOND B-CONTA, V84, P260, DOI 10.1098/rspb.1911.0073; WHITE, 1906, PHYS REV, V23, P382; ZELENY, 1906, PHYS REV, V23, P399 | AG4: 7 | AH4: 2 | AI4: 2 | AJ4: 0 | AK4: 0 | AL4: AMER CHEMICAL SOC | AM4: WASHINGTON | AN4: 1155 16TH ST, NW, WASHINGTON, DC 20036 USA | AO4: 0002-7863 | AR4: J AM CHEM SOC | AS4: J. Am. Chem. Soc. | AU4: 1928 | AV4: 50 | AX4: 2 | BB4: 2053 | BC4: 2065 | BE4: 10.1021/ja01395a001 | BI4: 13 | BJ4: Chemistry, Multidisciplinary | BK4: Chemistry | BL4: V8444 | BM4: WOS:000188448200142 | BR4: 43703
A5: 4 | B5: 10.1084/jem.49.5.711 | C5: J | D5: Coulter, CB; Isaacs, ML | H5: Coulter, CB; Isaacs, ML | K5: Oxidation-reduction equilibria in biological systems. II. Potentials of aerobic cultures of B-tyhosus. | L5: JOURNAL OF EXPERIMENTAL MEDICINE | O5: English | P5: Article | Y5: Columbia Univ, Coll Phys & Surg, Dept Bacteriol, New York, NY USA | AF5: CANNAN RK, 1926, PUB HEALTH REP S, P55; Cohen B, 1928, J GEN PHYSIOL, V11, P585, DOI 10.1085/jgp.11.5.585; Coulter CB, 1928, J GEN PHYSIOL, V12, P139, DOI 10.1085/jgp.12.1.139; Dixon M, 1927, P R SOC LOND B-CONTA, V101, P57, DOI 10.1098/rspb.1927.0005; Dixon M, 1923, J CHEM SOC, V123, P2943, DOI 10.1039/ct9232302943; Dubos R, 1929, J EXP MED, V49, P507, DOI 10.1084/jem.49.3.507; Gillespie LJ, 1920, SOIL SCI, V9, P199, DOI 10.1097/00010694-192004000-00001; MICHAELIS L., 1928, JOUR BIOL CHEM, V79, P689; Neill JM, 1926, J EXP MED, V44, P215, DOI 10.1084/jem.44.2.215; Neill JM, 1926, J EXP MED, V44, P227, DOI 10.1084/jem.44.2.227; Potter MC, 1911, P R SOC LOND B-CONTA, V84, P260, DOI 10.1098/rspb.1911.0073 | AG5: 11 | AH5: 12 | AI5: 12 | AJ5: 0 | AK5: 0 | AL5: ROCKEFELLER UNIV PRESS | AM5: NEW YORK | AN5: 1114 FIRST AVE, 4TH FL, NEW YORK, NY 10021 USA | AO5: 0022-1007 | AR5: J EXP MED | AS5: J. Exp. Med. | AT5: MAY | AU5: 1929 | AV5: 49 | AW5: 5 | BB5: 711 | BC5: 725 | BE5: 10.1084/jem.49.5.711 | BI5: 15 | BJ5: Immunology; Medicine, Research & Experimental | BK5: Immunology; Research & Experimental Medicine | BL5: V28TM | BM5: WOS:000201943400002 | BN5: 19869577 | BO5: Bronze, Green Published | BR5: 43703
A6: 5 | B6: 10.1042/bj0281894 | C6: J | D6: Messing, WA | H6: Messing, WA | K6: The mechanism of bacterial anaerobiosis. III. The oxidation-reduction potential of the butyric bacillus in presence of sulphydryl compounds. | L6: BIOCHEMICAL JOURNAL | O6: English | P6: Article | AF6: AUBEL, 1929, ANN PHYS PHYSICHOCHI, V5, P1; BAMBERGER, 1933, J GEN PHYSL, V16; CLARK, 1924, J WASH AC SC, V14, P123; COULTER, 1929, J EXP MED, V49, P711; FILDES, 1929, BRIT J EXP PATH, V10, P151; GILLESPIE, 1920, SOIL SCI, V9, P199; HEWITT, 1930, OXIDATION REDUCTION, P41; HOPKINS, 1931, P ROY SOC LOND B, V109, P58; HOSOYA, 1925, BACTERIAL METABOLISM, P79; KNIGHT, 1930, BIOCH J, V24, P1496; LEPPER, 1930, BRIT J EXP PATH, V11, P137; MESSING, 1933, MICROBIOLOGICA IMMUN; PLOTZ, 1930, ANN I PASTEUR, V45, P613; Potter MC, 1911, P R SOC LOND B-CONTA, V84, P260, DOI 10.1098/rspb.1911.0073; QUASTEL, 1926, BIOCHEM J, V20, P1126; QUASTEL, 1929, BIOCH J, V23, P115; TAROZZI, 1905, CENTR BAKT ABT 1, V38, P619; WURMSER, 1930, OXYDATIONS REDUCTION, P343 | AG6: 18 | AH6: 3 | AI6: 3 | AJ6: 0 | AK6: 0 | AL6: PORTLAND PRESS | AM6: LONDON | AN6: 59 PORTLAND PLACE, LONDON W1N 3AJ, ENGLAND | AO6: 0264-6021 | AR6: BIOCHEM J | AS6: Biochem. J. | AU6: 1934 | AV6: 28 | AX6: 2 | BB6: 1894 | BC6: 1900 | BE6: 10.1042/bj0281894 | BI6: 7 | BJ6: Biochemistry & Molecular Biology | BK6: Biochemistry & Molecular Biology | BL6: V4092 | BM6: WOS:000187145100094 | BN6: 16745587 | BR6: 43703
A7: 6 | C7: J | D7: Elema, B; Kluyver, AJ; van Dalfsen, JW | H7: Elema, B; Kluyver, AJ; van Dalfsen, JW | K7: The connection between the metabolism procedures of the micro organisms and of the oxido reduction potential in the medium I Announcement - Trials with denitrified bacteria | L7: BIOCHEMISCHE ZEITSCHRIFT | O7: German | P7: Article | Y7: Tech Hsch, Lab Mikrobiol, Delft, HOLLAND | AF7: BEIJERINCK MW, 1910, CENTRALBL BAKTERIO 2, V25, P30; Borsook H, 1931, J BIOL CHEM, V92, P535; Boyland E, 1930, BIOCHEM J, V24, P703, DOI 10.1042/bj0240703; COONS OC, 1931, IND ENG CHEM ANAL ED, V3, P407; ELEINA B, 1932, BEPALING OXYDATIE RE; Elema B, 1931, RECL TRAV CHIM PAY-B, V50, P807; ELEMA B, 1932, CHEM WEEKBL, V29, P638; ELEMA B, 1931, CHEM WEEKBL, V28, P219; Gayon U., 1882, CR HEBD ACAD SCI, V95, P644; HEWITT LF, 1931, OXIDATION REDUCTION; Kluyver A. J., 1931, CHEM ACTIVITIES MICR; KLUYVER AJ, 1926, CHEM GEWEBE, V13, P189; KUSNETZOW SJ, 1931, CENTRALBL BAKT, V83, P37; Lehmann J, 1930, SKAND ARCH PHYSIOL, V58, P173, DOI 10.1111/j.1748-1716.1930.tb00924.x; Lipmann F, 1934, BIOCHEM Z, V268, P205; Potter MC, 1911, P R SOC LOND B-CONTA, V84, P260, DOI 10.1098/rspb.1911.0073; Quastel JH, 1924, BIOCHEM J, V18, P519, DOI 10.1042/bj0180519; RASCHIG BF, 1924, SCHWEFEL STICKSTOFFS, P97; SZENTGYORGYI A, 1933, Z PHYSL CHEM, V217, P51; THUNBERG T, 1925, SKAND ARCH PHYSL, V46, P339; VANITERSON JG, 1904, CENTRALBL BAKT, V12, P106; VANNIEUWENBURG CJ, 1927, CHEM WEEKBL, V24, P202; WIDMARK EMP, 1922, BIOCHEM Z, V131, P471; Wurmser R, 1930, OXYDATIONS REDUCTION; WURMSER R, 1932, CR HEBD ACAD SCI, V194, P888 | AG7: 25 | AH7: 18 | AI7: 18 | AJ7: 0 | AK7: 0 | AL7: SPRINGER | AM7: NEW YORK | AN7: 233 SPRING STREET, NEW YORK, NY 10013 USA | AO7: 0366-0753 | AR7: BIOCHEM Z | AS7: Biochem. Z. | AU7: 1934 | AV7: 270 | BB7: 317 | BC7: 340 | BI7: 24 | BJ7: Biochemistry & Molecular Biology | BK7: Biochemistry & Molecular Biology | BL7: V12RW | BM7: WOS:000200857600033 | BR7: 43703
A8: 7 | C8: J | D8: Kluyver, AJ; Hoogerheide, JC | H8: Kluyver, AJ; Hoogerheide, JC | K8: Some remarks on the reduction intensity of living cells | L8: PROCEEDINGS OF THE KONINKLIJKE AKADEMIE VAN WETENSCHAPPEN TE AMSTERDAM | O8: English | P8: Article | AF8: AVERY RC, 1922, BACT ABSTRACTS, V6, P31; Borsook H, 1931, J BIOL CHEM, V92, P535; CLARK WM, 1925, 8 PUBL HLTH WASH, V40, P1131; CLARK WM, 1928, PUBLIC HLTH SERVICE, V151; EHRLICH P, 1885, FARBEN ANAL STUDIE; Elema B, 1934, BIOCHEM Z, V270, P317; ELEMA B, 1932, BEPALING OXYDATIE RE; Fromageot C, 1935, BIOCHEM Z, V279, P34; Gillespie LJ, 1920, SOIL SCI, V9, P199, DOI 10.1097/00010694-192004000-00001; HELMHOLTZ H, 1844, J PRAKT CHEM, V31, P429; HEWITT LF, 1935, OXIDATION REDUCTION; HOOGERHEIDE JC, 1935, BIJDRAGE KENNIS REAC; Kluyver AJ, 1934, BIOCHEM Z, V272, P197; LEHMANN J, 1925, SKAND ARCH PHYSL, V46, P339; MICHAELIS L, 1933, OXYDATIONS REDUCTION; Potter MC, 1911, P R SOC LOND B-CONTA, V84, P260, DOI 10.1098/rspb.1911.0073; Quastel JH, 1924, BIOCHEM J, V18, P519, DOI 10.1042/bj0180519; RUDOLF J, 1926, CENTRALBL BAKT 1, V100, P147; SHERMAN JM, 1918, J BACTERIOL, V3, P168; SZENTGYORGYI A, 1933, Z PHYSL CHEM, V217, P51; Wurmser R, 1932, CR HEBD ACAD SCI, V195, P81; WURMSER R, 1935, ELECTROACTIVITE CHIM; Wurmser R, 1930, OXYDATIONS REDUCTION; Yudkin J, 1935, BIOCHEM J, V29, P1130, DOI 10.1042/bj0291130 | AG8: 24 | AH8: 0 | AI8: 0 | AJ8: 1 | AK8: 2 | AL8: ELSEVIER SCIENCE BV | AM8: AMSTERDAM | AN8: PO BOX 211, 1000 AE AMSTERDAM, NETHERLANDS | AR8: P K AKAD WET-AMSTERD | AS8: Proc. K. Akad. Wet.-Amsterdam | AU8: 1936 | AV8: 39 | AW8: 43586 | BB8: 298 | BC8: 305 | BI8: 8 | BJ8: Multidisciplinary Sciences | BK8: Science & Technology - Other Topics | BL8: V37IW | BM8: WOS:000202524200041 | BR8: 43703
A9: 8 | B9: 10.2307/2436655 | C9: J | D9: McAlister, DF | H9: McAlister, DF | K9: Effect of fungi on the oxidation-reduction potentials of liquid culture media | L9: AMERICAN JOURNAL OF BOTANY | O9: English | P9: Article | Y9: US Dept Agr, Bureau Plant Ind, Logan, UT USA | AF9: AUBEL E, 1929, ANN PHYSL PHYSICOCHI, V5, P1; CANNAN RK, 1926, US PUBLIC HLTH REP S, V55; CLARK WM, 1923, US PUB HLTH REPTS, V38, P666; Haber F, 1909, Z PHYS CHEM-STOCH VE, V67, P385; HEWITT LF, 1933, OXIDATION REDUCTION; Kluyver AJ, 1934, BIOCHEM Z, V272, P197; Partridge HM, 1929, J AM CHEM SOC, V51, P1, DOI 10.1021/ja01376a001; Pinckard JA, 1935, J AGRIC RES, V50, P0933; Potter MC, 1911, P R SOC LOND B-CONTA, V84, P260, DOI 10.1098/rspb.1911.0073; RICHARDS HM, 1997, JB WISSENSCHAFTLICHE, V30, P665; Robbins WJ, 1937, AM J BOT, V24, P243, DOI 10.2307/2436609; Tang PS, 1936, J CELL COMPAR PHYSL, V9, P149, DOI 10.1002/jcp.1030090113 | AG9: 12 | AH9: 4 | AI9: 4 | AJ9: 0 | AK9: 0 | AL9: BOTANICAL SOC AMER INC | AM9: COLUMBUS | AN9: OHIO STATE UNIV-DEPT BOTANY, 1735 NEIL AVE, COLUMBUS, OH 43210 USA | AO9: 0002-9122 | AR9: AM J BOT | AS9: Am. J. Bot. | AT9: APR | AU9: 1938 | AV9: 25 | AW9: 4 | BB9: 286 | BC9: 295 | BE9: 10.2307/2436655 | BI9: 10 | BJ9: Plant Sciences | BK9: Plant Sciences | BL9: V06XF | BM9: WOS:000200465900008 | BR9: 43703
A10: 9 | C10: J | D10: Ward, WE | H10: Ward, WE | K10: The apparent oxidation-reduction potentials of bright platinum electrodes in synthetic media cultures of bacteria | L10: JOURNAL OF BACTERIOLOGY | O10: English | P10: Article | Y10: Univ Chicago, Dept Bacteriol & Parasitol, Chicago, IL USA | AF10: Allyn WP, 1932, J BACTERIOL, V23, P369; Elema B, 1934, BIOCHEM Z, V270, P317; GILLESPIE RWH, 1934, J BACTERIOL, V31, P14; KLUYVER AJ, 1936, ENZYMOLOGIA, V1, P1; Knight BCJG, 1937, BIOCHEM J, V31, P731, DOI 10.1042/bj0310731; Koser SA, 1935, J INFECT DIS, V56, P305, DOI 10.1093/infdis/56.3.305; Koser SA, 1936, J INFECT DIS, V58, P121, DOI 10.1093/infdis/58.1.121; Longsworth LG, 1936, J BACTERIOL, V32, P567; Mudge CS, 1933, P SOC EXP BIOL MED, V31, P154; Mueller JH, 1937, J BACTERIOL, V34, P381; Mueller JH, 1937, J BACTERIOL, V34, P429; Potter MC, 1911, P R SOC LOND B-CONTA, V84, P260, DOI 10.1098/rspb.1911.0073; Sahyun M, 1936, J INFECT DIS, V58, P28, DOI 10.1093/infdis/58.1.28 | AG10: 13 | AH10: 5 | AI10: 5 | AJ10: 0 | AK10: 0 | AL10: AMER SOC MICROBIOLOGY | AM10: WASHINGTON | AN10: 1752 N ST NW, WASHINGTON, DC 20036-2904 USA | AO10: 0021-9193 | AR10: J BACTERIOL | AS10: J. Bacteriol. | AT10: OCT | AU10: 1938 | AV10: 36 | AW10: 4 | BB10: 337 | BC10: 355 | BI10: 19 | BJ10: Microbiology | BK10: Microbiology | BL10: V00ZC | BM10: WOS:000200065200001 | BN10: 16560157 | BR10: 43703
A11: 10 | C11: J | D11: Gillespie, RWH; Rettger, LF | H11: Gillespie, RWH; Rettger, LF | K11: Bacterial oxidation-reduction studies I Differentiation of species of the spore-forming anaerobes by potentiometric technique | L11: JOURNAL OF BACTERIOLOGY | O11: English | P11: Article | Y11: Yale Univ, Dept Bacteriol, New Haven, CT USA | AF11: BOYD ELDON M., 1931, CANADIAN JOUR RES, V4, P605; BOYD ELDON M., 1931, CANADIAN JOUR RES, V4, P54; Burrows W, 1936, J INFECT DIS, V58, P259, DOI 10.1093/infdis/58.3.259; Burrows W, 1935, J INFECT DIS, V56, P255, DOI 10.1093/infdis/56.3.255; CANNAN RK, 1926, STUDIES OXIDATION S, V55; CLARK WM, 1923, STUDIES OXIDATION RE, V38, P933; CLARK WM, 1923, STUDIES OXIDATION RE, V38, P666; DuBois D, 1930, J BIOL CHEM, V88, P729; Gillespie LJ, 1920, SOIL SCI, V9, P199, DOI 10.1097/00010694-192004000-00001; GILLESPIE RWH, 1936, J BACTERIOL, V31, P101; GILLESPIE RWH, 1936, J BACTERIOL, V31, P14; GILLESPIE RWH, 1937, J BACTERIOL, V33, P112; Hewitt LF, 1930, BIOCHEM J, V24, P1551, DOI 10.1042/bj0241551; Hewitt LF, 1931, BIOCHEM J, V25, P1452, DOI 10.1042/bj0251452; Hewitt LF, 1931, BIOCHEM J, V25, P2068, DOI 10.1042/bj0252068; Hewitt LF, 1931, BIOCHEM J, V25, P1641, DOI 10.1042/bj0251641; Hewitt LF, 1931, BIOCHEM J, V25, P1447, DOI 10.1042/bj0251447; Hewitt LF, 1930, BIOCHEM J, V24, P669, DOI 10.1042/bj0240669; Hewitt LF, 1930, BIOCHEM J, V24, P676, DOI 10.1042/bj0240676; Hewitt LF, 1931, BIOCHEM J, V25, P858, DOI 10.1042/bj0250858; Hewitt LF, 1930, BIOCHEM J, V24, P512, DOI 10.1042/bj0240512; Hewitt LF, 1931, BIOCHEM J, V25, P169, DOI 10.1042/bj0250169; HEWITT LF, 1933, OXIDATION REDUCTION, P81; Knight BCJG, 1930, BIOCHEM J, V24, P1075, DOI 10.1042/bj0241075; Knight BCJG, 1930, BIOCHEM J, V24, P1066, DOI 10.1042/bj0241066; Lepper E, 1930, BRIT J EXP PATHOL, V11, P140; Lepper EH, 1931, BIOCHEM J, V25, P45, DOI 10.1042/bj0250045; PLOTZ HARRY, 1930, ANN INST PASTEUR [PARIS], V45, P613; Potter MC, 1911, P R SOC LOND B-CONTA, V84, P260, DOI 10.1098/rspb.1911.0073; Sagen HE, 1934, J BACTERIOL, V28, P571; Tuttle CD, 1934, J INFECT DIS, V54, P259, DOI 10.1093/infdis/54.2.259 | AG11: 31 | AH11: 7 | AI11: 7 | AJ11: 0 | AK11: 0 | AL11: AMER SOC MICROBIOLOGY | AM11: WASHINGTON | AN11: 1752 N ST NW, WASHINGTON, DC 20036-2904 USA | AO11: 0021-9193 | AR11: J BACTERIOL | AS11: J. Bacteriol. | AT11: DEC | AU11: 1938 | AV11: 36 | AW11: 6 | BB11: 605 | BC11: 620 | BI11: 16 | BJ11: Microbiology | BK11: Microbiology | BL11: V00ZE | BM11: WOS:000200065400004 | BN11: 16560179 | BR11: 43703
A12: 11 | B12: 10.1126/science.137.3530.615 | C12: J | D12: DAVIS, JB; YARBROUGH, HF | H12: DAVIS, JB; YARBROUGH, HF | K12: PRELIMINARY EXPERIMENTS ON A MICROBIAL FUEL CELL | L12: SCIENCE | O12: English | P12: Article | AF12: Cohen B., 1931, J BACTERIOL, V21, P18; HANSEN RW, 1957, SCIENCE, V125, P1198, DOI 10.1126/science.125.3259.1198; MASON HS, 1957, ADV ENZYMOL REL S BI, V19, P79; Potter MC, 1911, P R SOC LOND B-CONTA, V84, P260, DOI 10.1098/rspb.1911.0073; STEWART JE, 1959, J BACTERIOL, V78, P441 | AG12: 5 | AH12: 88 | AI12: 91 | AJ12: 2 | AK12: 99 | AL12: AMER ASSOC ADVANCEMENT SCIENCE | AM12: WASHINGTON | AN12: 1200 NEW YORK AVE, NW, WASHINGTON, DC 20005 | AO12: 0036-8075 | AR12: SCIENCE | AS12: Science | AU12: 1962 | AV12: 137 | AW12: 3530 | BB12: 615 | BC12: & | BE12: 10.1126/science.137.3530.615 | BI12: 0 | BJ12: Multidisciplinary Sciences | BK12: Science & Technology - Other Topics | BL12: 3025C | BM12: WOS:A19623025C00005 | BN12: 17836545 | BR12: 43703
A13: 12 | B13: 10.1002/jobm.3630050105 | C13: J | D13: JACOB, HE; HORN, G | H13: JACOB, HE; HORN, G | K13: KONTINUIERLICHE REGISTRIERUNG PHYSIKOCHEMISCHER MESSGROSSEN IN BAKTERIENKULTUREN .2. DER EINFLUSS VON GELOSTSAUERSTOFF AUF REDOXPOTENTIALMESSUNGEN IN BAKTERIENKULTUREN | L13: ZEITSCHRIFT FUR ALLGEMEINE MIKROBIOLOGIE | O13: English | P13: Article | AF13: ALDERTON G, 1945, J BIOL CHEM, V157, P43; ALDERTON G, 1946, J BIOL CHEM, V164, P1; Breed RS, 1957, BERGEYS MANUAL DETER; CAPPELLATO M., 1960, BOLL IST SIERQTERAP MILAN, V39, P40; CATER DB, 1957, PROC R SOC SER B-BIO, V146, P382, DOI 10.1098/rspb.1957.0019; CATER DB, 1957, PROC R SOC SER B-BIO, V146, P400, DOI 10.1098/rspb.1957.0020; FLASCHENTRAGER B, 1951, PHYSIOLOGISCHE CHEMI; Fleming A, 1922, P R SOC LOND B-CONTA, V93, P306, DOI 10.1098/rspb.1922.0023; Gillespie LJ, 1920, SOIL SCI, V9, P199, DOI 10.1097/00010694-192004000-00001; GOLDBACH W, 1963, ACTA BIOL MED GER, V10, P579; GOLDBACH W, 1961, 2 ATT S INT LIS FLEM, P131; GOLDBACH W, 1962, Z ALLG MIKROBIOL, V2, P185; HAVEMANN R, 1959, Z PHYS CHEM, V211, P267; Hewitt L.F., 1950, OXIDATION REDUCTION; HORN G, 1963, MONATSBERICHTE DEUTS, V5, P227; HORN G, 1964, CHEM TECHN, V16, P237; HORN G, IN PREPARATION; HOUBENWEIL, 1955, METHODEN ORGANISCHEN; INOUE K, 1959, BIKEN J, V2, P1; JACOB HE, IN PREPARATION; JACOB HE, 1964, HYG 1, V192, P315; JACOB HE, 1964, ABH AKAD WISS BERLIN, P320; JOLLES P, 1960, BIOCHIM BIOPHYS ACTA, V39, P212, DOI 10.1016/0006-3002(60)90155-4; JOLLES P, 1957, CR SOC BIOL, V151, P1368; JOLLES P, 1964, ANGEW CHEM, V76, P20; KONIG E, 1964, Z CHEM, V4, P95; KOVACS E, 1958, NATURWISSENSCHAFTEN, V45, P285, DOI 10.1007/BF00622873; KOVACS E, 1957, NATURWISSENSCHAFTEN, V44, P280, DOI 10.1007/BF00597329; LENGYEL Z, 1962, AEROB FERMENTACIOK O; MALKE H., 1964, Z ALLG MIRROBIOL, V4, P88, DOI 10.1002/jobm.3630040108; MATKOVICS B, 1958, NATURWISSENSCHAFTEN, V45, P168, DOI 10.1007/BF00622011; MATKOVICS B., 1959, SCHWEIZ ZEITSCHR ALLG PATH U BAKT, V22, P214; Meyer K, 1936, J BIOL CHEM, V113, P303; MICHAELIS L, 1933, OXYDATIONS REDUKTION; MUSCHEL LH, 1959, J IMMUNOL, V82, P38; NETTER H, 1959, THEORETISCHE BIOCHEM; Potter MC, 1911, P R SOC LOND B-CONTA, V84, P260, DOI 10.1098/rspb.1911.0073; RABOTNOWA I, 1963, BEDEUTUNG PHYSIKALIS; RICHMOND MH, 1957, J GEN MICROBIOL, V16, pR4; RUMMENI G, 1954, WISS Z U JENA MN, V4, P611; RUMMENI G, 1954, BER DTSCH BOT GES, V67, P335; SALTON MRJ, 1957, BACTERIOL REV, V21, P82; SMITH EL, 1955, J BIOL CHEM, V215, P67; SMITH GN, 1949, ARCH BIOCHEM, V21, P383; SQUIRES RW, 1958, IND ENG CHEM, V50, P1263, DOI 10.1021/ie50585a032; Steinhaus EA, 1949, PRINCIPLES INSECT PA; STROHBACH G, 1963, THESIS JENA; TENGERDY RP, 1962, J BIOCHEM MICROBIOL, V3, P255; TENGERDY RP, 1962, J BIOCH MICROBIOL TE, V3, P241; TODT F, 1958, ELEKTROCHEMISCHE SAU; VETTER K, 1961, ELEKTROCHEMISCHE KIN; VONSTACKELBERG M, 1955, METHODEN ORGANISCHEN; WAGNER RR, 1961, BACTERIOL REV, V25, P100; WARTENBERG H, 1953, WISS Z SCHILLER U JE, V2, P53; WARTENBERG HANS, 1957, BER DEUTSCH BOT GES, V70, P79; WEIDEL W, 1958, J GEN MICROBIOL, V18, P513, DOI 10.1099/00221287-18-2-513; ZIEGLER E, 1960, ARZNEIMITTEL FORSCHU | AG13: 57 | AH13: 10 | AI13: 10 | AJ13: 0 | AK13: 0 | AL13: AKADEMIE VERLAG GMBH | AM13: BERLIN | AN13: MUHLENSTRASSE 33-34, D-13187 BERLIN, GERMANY | AO13: 0044-2208 | AR13: Z ALLG MIKROBIOL | AU13: 1965 | AV13: 5 | AW13: 1 | BB13: 33 | BC13: & | BE13: 10.1002/jobm.3630050105 | BI13: 0 | BJ13: Biotechnology & Applied Microbiology; Microbiology | BK13: Biotechnology & Applied Microbiology; Microbiology | BL13: 63699 | BM13: WOS:A19656369900004 | BN13: 4961479 | BR13: 43703
A14: 13 | B14: 10.1002/bit.260080410 | C14: J | D14: YOUNG, TG; HADJIPETROU, L; LILLY, MD | H14: YOUNG, TG; HADJIPETROU, L; LILLY, MD | K14: THEORETICAL ASPECTS OF BIOCHEMICAL FUEL CELLS | L14: BIOTECHNOLOGY AND BIOENGINEERING | O14: English | P14: Article | AF14: BENJAMIN L, 1955, REPORT CENTR ELECTRI; Clark W. M., 1960, OXIDATION REDUCTION; Cohen B., 1931, J BACTERIOL, V21, P18; DELDUCA MG, 1962, P ANNU POWER SOURCE, V16, P81; GOLDMER BH, 1962, P ANNU POWER SOURCE, V16, P70; Gunsalus I. C., 1961, BACTERIA, V2, P1; Hewitt L.F., 1950, OXIDATION REDUCTION; LILLY M, 1965, BIOCHEM J, V95, pP45; LONGMUIR IS, 1954, BIOCHEM J, V57, P81, DOI 10.1042/bj0570081; MAY PS, 1964, P ANNU POWER SOURCE, V18, P1; Michaelis L, 1913, BIOCHEM Z, V49, P333; Monod J., 1942, RECHERCHES CROISSANC; Potter MC, 1911, P R SOC LOND B-CONTA, V84, P260, DOI 10.1098/rspb.1911.0073; Wood WA, 1961, BACTERIA, VII, P59 | AG14: 14 | AH14: 13 | AI14: 13 | AJ14: 2 | AK14: 5 | AL14: WILEY | AM14: HOBOKEN | AN14: 111 RIVER ST, HOBOKEN 07030-5774, NJ USA | AO14: 0006-3592 | AP14: 1097-0290 | AR14: BIOTECHNOL BIOENG | AS14: Biotechnol. Bioeng. | AU14: 1966 | AV14: 8 | AW14: 4 | BB14: 581 | BC14: + | BE14: 10.1002/bit.260080410 | BI14: 1 | BJ14: Biotechnology & Applied Microbiology | BK14: Biotechnology & Applied Microbiology | BL14: 86984 | BM14: WOS:A19668698400009 | BR14: 43703
A15: 14 | C15: J | D15: CENEK, M | H15: CENEK, M | K15: BIOCHEMICAL FUEL CELLS | L15: CHEMICKE LISTY | O15: English | P15: Review | AF15: ALLEN MJ, 1963, ELECTROCHIM ACTA, V8, P419; BERK RS, 1964, APPL MICROBIOL, V12, P10; BLANCHARD GC, 1963, 17 P ANN POW SOURC C; BOYER MH, 1964, STUDY BASIC BIOELECT; BOYER MH, 1963, STUDY BASIC BIOELECT; BRAKE JM, 1963, 3 MAGN CORP QUART PR; BRAKE JM, 1963, 5 MAGN CORP QUART PR; BRAKE JM, 1963, 17 ANN P POW SOURC C; BRAKE JM, 1963, 4 MAGN CORP QUART PR; CAVALLO JJ, 1964, 7 MAGN CORP QUART PR; CLARK WM, 1960, OXIDATIONREDUCTION P; Cohen B., 1931, J BACTERIOL, V21, P18; COHN ME, 1963, DEV IND MICROBIOL, V4, P53; ELLIS GE, 1963, 2 MARQ CORP QUART RE; ELLIS GE, 1963, 1 MARQ CORP QUART PR; ELLIS GE, 1964, 3 MARQ CORP QUART PR; EULER J, 1964, ETZB, V16, P16; HAACKE O, 1892, FLORA, P75; HAMPEL CA, 1964, ENCYCLOPEDIA ELECTRO, P103; KARLSON P, 1965, ZAKLADY BIOCHEMIE, P206; KONIKOFF JJ, 1963, ELECTRICAL ENERGY BI; KOSTIR J, 1965, CHEMIE FYSIKA ZIVYCH, P215; Potter MC, 1911, P R SOC LOND B-CONTA, V84, P260, DOI 10.1098/rspb.1911.0073; ROHRBACK GH, 1962, 16 ANN P POW SOURC C; ROSENWALD AJ, 1962, APPL MICROBIOL, V10, P345; SCOTT WR, 1962, SEP P EL WORK GROUP; SHAW M, 1963, 17 ANN P POW SOURC C; SISLER FD, 1961, NEW SCI, V12, P256; SISLER FD, 1964, GLOBAL IMPACTS APPLI; SUZUKI, 1964, CHEM CHEM IND, V17, P1359; SUZUKI M, 1964, J CHEM SOC JAP, V67, P410; SUZUKI M, 1962, J CHEM SOC JAP, V65, P1606; SUZUKI M, 1964, 31 C EL SOC JAP; SUZUKI M, 1964, J CHEM SOC JAP, V67, P1887; TAYLOR JE, 1963, CHEM ING PROGR, V59, P10; WILLIAM KR, 1966, INTRODUCTION FUEL CE, P256; WILSON BJ, 1962, NOV P BIOCH FUEL CEL; YAHIRO AT, 1964, BIOCHIM BIOPHYS ACTA, V88, P375, DOI 10.1016/0926-6577(64)90192-5; 1964, ELEC REV, V10, P46 | AG15: 39 | AH15: 15 | AI15: 15 | AJ15: 0 | AK15: 0 | AL15: CHEMICKE LISTY | AM15: PRAGUE 6 | AN15: PELLEOVA 24, PRAGUE 6 160 00, CZECH REPUBLIC | AO15: 0009-2770 | AR15: CHEM LISTY | AS15: Chem. Listy | AU15: 1968 | AV15: 62 | AW15: 8 | BB15: 927 | BC15: & | BI15: 0 | BJ15: Chemistry, Multidisciplinary | BK15: Chemistry | BL15: B6999 | BM15: WOS:A1968B699900003 | BR15: 43703
A16: 15 | B16: 10.1177/00220345690480053101 | C16: J | D16: PARKER, RB | H16: PARKER, RB | K16: BIOELECTRIC PHENOMENA IN DENTAL DECAY | L16: JOURNAL OF DENTAL RESEARCH | O16: English | P16: Article | AF16: BARKER RB, 1964, LIFE SCI, V3, P1275; BECKER RO, 1964, INT S BONE DYNAMICS, P209; BRIDGMAN WK, 1961, T ODONT SOC GR BRIT, V111, P369; CHICK AO, 1963, J DENT RES, V42, P934, DOI 10.1177/00220345630420041801; FUKADA E, 1957, J PHYS SOC JPN, V12, P1158, DOI 10.1143/JPSJ.12.1158; HORVATH J, 1960, ACTA CHIM HUNG, V25, P65; Klein H, 1929, J DENT RES, V9, P667; LEWIS K, 1966, BACTERIOL REV, V30, P101; MANLY RS, 1966, ARCH ORAL BIOL, V11, P931, DOI 10.1016/0003-9969(66)90083-5; MAYUZUMI Y, 1964, J DENT RES, V43, P941; PARKER RB, 1967, ARCH ORAL BIOL, V12, P131, DOI 10.1016/0003-9969(67)90149-5; Potter MC, 1911, P R SOC LOND B-CONTA, V84, P260, DOI 10.1098/rspb.1911.0073; RINDNER W, 1962, B AM PHYS SOC, V7, P65; WOOLLEY L, 1966, THESIS U OREGON DENT | AG16: 14 | AH16: 0 | AI16: 1 | AJ16: 0 | AK16: 0 | AL16: AMER ASSOC DENTAL RESEARCH | AM16: ALEXANDRIA | AN16: 1619 DUKE ST, ALEXANDRIA, VA 22314 | AO16: 0022-0345 | AR16: J DENT RES | AS16: J. Dent. Res. | AU16: 1969 | AV16: 48 | AW16: 5P1S | BB16: 795 | BC16: & | BE16: 10.1177/00220345690480053101 | BI16: 0 | BJ16: Dentistry, Oral Surgery & Medicine | BK16: Dentistry, Oral Surgery & Medicine | BL16: E4365 | BM16: WOS:A1969E436500030 | BN16: 5259419 | BR16: 43703
A17: 16 | B17: 10.1149/1.2408290 | C17: J | D17: BLANCHARD, GC; FOLEY, RT | H17: BLANCHARD, GC; FOLEY, RT | K17: OPERATION OF AN ION-MEMBRANE FUEL CELL WITH MICROBIALLY-PRODUCED HYDROGEN | L17: JOURNAL OF THE ELECTROCHEMICAL SOCIETY | O17: English | P17: Article | AF17: ABEL K, 1964, ANAL CHEM, V36, P954, DOI 10.1021/ac60210a085; BLANCHARD GC, 1963, 17 P ANN POW SOURC C; BLANCHARD GC, TO BE PUBLISHED; BLANCHARD GC, 1965, 149 AM CHEM SOC M DE; BOYD ELDON M., 1931, CANADIAN JOUR RES, V4, P605; Clifton CE, 1934, J BACTERIOL, V28, P541; Cohen B., 1931, J BACTERIOL, V21, P18; HAYNES WC, 1955, APPL MICROBIOL, V3, P361; Johnstone KI, 1942, J PATHOL BACTERIOL, V54, P25, DOI 10.1002/path.1700540104; KRICHEVSKY M, 1961, J BIOL CHEM, V236, P2520; LEWIS K, 1966, BACTERIOL REV, V30, P101; MAY PJ, 1964, 18 P ANN POW SOURC C; PERRY J, 1965, 19 P ANN POW SOURC C, P19; Potter MC, 1911, P R SOC LOND B-CONTA, V84, P260, DOI 10.1098/rspb.1911.0073; QUINN LY, 1964, PERSONAL COMMUNICATI; ROHRBACK GH, 1962, 16 ANN POW SOURC C A; SILVERMAN HP, 1962, DA36039SC90866 CONTR; SISLER FD, 1961, NEW SCIENTIST, V12, P110; WILSON BJ, 1963, NRL5998 REP | AG17: 19 | AH17: 3 | AI17: 3 | AJ17: 0 | AK17: 1 | AL17: ELECTROCHEMICAL SOC INC | AM17: PENNINGTON | AN17: 65 SOUTH MAIN STREET, PENNINGTON, NJ 08534 USA | AO17: 0013-4651 | AP17: 1945-7111 | AR17: J ELECTROCHEM SOC | AS17: J. Electrochem. Soc. | AU17: 1971 | AV17: 118 | AW17: 7 | BB17: 1232 | BC17: + | BE17: 10.1149/1.2408290 | BI17: 1 | BJ17: Electrochemistry; Materials Science, Coatings & Films | BK17: Electrochemistry; Materials Science | BL17: J6909 | BM17: WOS:A1971J690900050 | BR17: 43703
A18: 17 | B18: 10.1002/jobm.3630110809 | C18: J | D18: JACOB, HE | H18: JACOB, HE | K18: REDOX POTENTIAL IN BACTERIA CULTURES | L18: ZEITSCHRIFT FUR ALLGEMEINE MIKROBIOLOGIE | O18: German | P18: Article | AF18: BARD AJ, 1961, ANAL CHEM, V33, P11, DOI 10.1021/ac60169a002; BARTELS H, 1959, NATURWISSENSCHAFTEN, V46, P672, DOI 10.1007/BF00594822; BAUMBERGER IH, 1939, COLD SPRING HARBOR S, V7, P318; BELJUSTIN AA, 1964, BER AKAD WISS USSR, V154, P404; BERG HC, IN PRESS; BOCKRIS JO, 1970, MODERN ELECTROCHEMIS; Breed RS, 1957, BERGEYS MANUAL DETER; BREITER MW, 1962, J ELECTROCHEM SOC, V109, P425, DOI 10.1149/1.2425436; BREITER MW, 1962, ELECTROCHIM ACTA, V7, P601; CATER DB, 1957, PROC R SOC SER B-BIO, V146, P382, DOI 10.1098/rspb.1957.0019; CATER DB, 1957, P ROY SOC LONDON B, V146, P288; CLARK LC, 1953, J APPL PHYSIOL, V6, P189; Clark W. M., 1960, OXIDATION REDUCTION; COHEN B, 1957, MANUAL MICROBIOLOGIC, P72; DRAWERT H, 1956, HDB PFLANZENPHYSIOLO, P252; Gillespie LJ, 1920, SOIL SCI, V9, P199, DOI 10.1097/00010694-192004000-00001; GINER VJ, 1960, Z ELEKTROCHEM, V64, P491; Gray-Young T., 1966, BIOTECHNOL BIOENG, V8, P581; GRECHUSHKINA N. N., 1965, MIKROBIOLOGIYA, V34, P200; GROSZ HJ, 1967, NATURE, V213, P717, DOI 10.1038/213717a0; Harrop GA, 1928, J EXP MED, V48, P207, DOI 10.1084/jem.48.2.207; HAVEMANN R, 1959, Z PHYS CHEM, V211, P267; HEIDENREICH J, 1970, EXPERIENTIA, V26, P257, DOI 10.1007/BF01900080; Hewitt L.F., 1950, OXIDATION REDUCTION; HOARE JP, 1963, J ELECTROCHEM SOC, V110, P1019, DOI 10.1149/1.2425914; HOARE JP, 1965, J ELECTROCHEM SOC, V112, P602, DOI 10.1149/1.2423616; HORN H, 1964, Z ALLG MIKR, V4, P1; HORN H, 1966, ANTIBIOTICS ADVANCES, P761; Jacob H.E., 1970, METHOD MICROBIOL, V2, P91; JACOB HE, 1967, Z ALLG MIKROBIOL, V7, P407, DOI 10.1002/jobm.3630070510; JACOB HE, 1965, Z ALLG MIKROBIOL, V5, P33, DOI 10.1002/jobm.3630050105; JACOB HE, 1969, ENZYMOLOGIA, V36, P313; JACOB HE, 1969, STUD BIOPHYS, V14, P151; JACOB HE, 1966, MBER DTSCH AKAD WISS, V8, P924; KANTERE VM, 1971, 1 INT S BIOL ASP E; KONIG E, 1964, Z CHEM, V4, P95; KORDATZKI W, 1953, ARCH PHARM, V286, P43; KOVACS E, 1958, NATURWISSENSCHAFTEN, V45, P285, DOI 10.1007/BF00622873; LEMAN A, 1965, ARCH MIKROBIOL, V50, P357, DOI 10.1007/BF00509577; LEMAN A, 1965, ARCH MIKROBIOL, V50, P194, DOI 10.1007/BF00409128; LEMAN A, 1965, ARCH MIKROBIOL, V55, P134; LENGYEL ZL, 1965, BIOTECHNOL BIOENG, V7, P91, DOI 10.1002/bit.260070120; LENGYEL ZL, 1961, 5 INT C BIOL CHEM MO; LEPETIT G, 1962, CHEM TECHN, V14, P471; Lepper E, 1930, BRIT J EXP PATHOL, V11, P140; Lepper EH, 1931, BIOCHEM J, V25, P45, DOI 10.1042/bj0250045; LOESCHE WJ, 1969, APPL MICROBIOL, V18, P723; MAREK N, 1966, ACTA BIOL ACAD SCI H, V16, P319; MATVOVICS B, 1959, SCHWEIZ Z ALLG PATHO, V22, P214; MEISEL MN, 1952, MIKROBIOLOGIA, V11, P51; MICHAELIS L, 1929, OXYDATIONS REDUKTION; Potter MC, 1911, P R SOC LOND B-CONTA, V84, P260, DOI 10.1098/rspb.1911.0073; POTTER MC, 1910, DURHAM U PHIL SOC P, V3; RABOTNOWA I, 1963, BEDEUTUNG PHYSIKALIS; SCHLEGEL HG, 1969, ALLGEMEINE MIKROBIOL; SCHULDINER S, 1966, J ELECTROCHEM SOC, V113, P573, DOI 10.1149/1.2424029; SQUIRES RW, 1958, IND ENG CHEM, V50, P1263, DOI 10.1021/ie50585a032; TELCS I, 1968, ACTA CHIM HUNG, V58, P417; TENGERDY RP, 1961, J BIOCHEM MICROBIOL, V3, P241, DOI 10.1002/jbmte.390030304; THIMANN KV, 1964, LEBEN BAKTERIEN; VETTER K, 1961, ELEKTROCHEMISCHE KIN; Wartenberg H, 1939, BIOCHEM Z, V302, P262; WARTENBERG H, 1958, WISS Z FRIEDRICH MIV, V8, P193; WARTENBERG HANS, 1957, BER DEUTSCH BOT GES, V70, P79; WIMPENNY JW, 1969, BIOTECHNOL BIOENG, V11, P623, DOI 10.1002/bit.260110409; WROBLOWA H, 1967, J ELECTROANAL CHEM, V15, P139, DOI 10.1016/0022-0728(67)85018-6 | AG18: 66 | AH18: 7 | AI18: 7 | AJ18: 0 | AK18: 0 | AL18: AKADEMIE VERLAG GMBH | AM18: BERLIN | AN18: MUHLENSTRASSE 33-34, D-13187 BERLIN, GERMANY | AO18: 0044-2208 | AR18: Z ALLG MIKROBIOL | AU18: 1971 | AV18: 11 | AW18: 8 | BB18: 691 | BC18: & | BE18: 10.1002/jobm.3630110809 | BI18: 0 | BJ18: Biotechnology & Applied Microbiology; Microbiology | BK18: Biotechnology & Applied Microbiology; Microbiology | BL18: L6508 | BM18: WOS:A1971L650800008 | BN18: 4947991 | BR18: 43703
A19: 18 | B19: 10.1002/bit.260171011 | C19: J | D19: VIDELA, HA; ARVIA, AJ | H19: VIDELA, HA; ARVIA, AJ | K19: RESPONSE OF A BIOELECTROCHEMICAL CELL WITH SACCHAROMYCES-CEREVISIAE METABOLIZING GLUCOSE UNDER VARIOUS FERMENTATION CONDITIONS | L19: BIOTECHNOLOGY AND BIOENGINEERING | O19: English | P19: Article | Y19: UNIV NACL LA PLATA,FAC CIENCIAS EXACTAS,INST INVEST FISICOQUIM TEORICAS & APLICADAS,DIV,LA PLATA,ARGENTINA | AF19: Gray-Young T., 1966, BIOTECHNOL BIOENG, V8, P581; JACOB HE, 1970, METHODS MICROBIOLOGY, V2, P105; JOHNSON MJ, 1964, BIOTECHNOL BIOENG, V6, P457, DOI 10.1002/bit.260060407; MARTINS ME, 1969, AN ASOC QUIM ARGENT, V57, P91; MAXON WD, 1953, IND ENG CHEM, V45, P2554, DOI 10.1021/ie50527a051; PAUS G, 1971, AN SOC CIENT ARGENT, V192, P35; Potter MC, 1911, P R SOC LOND B-CONTA, V84, P260, DOI 10.1098/rspb.1911.0073; RUIZAMIL M, 1956, ARCH MIKROBIOL, V55, P46; SOLS A, 1971, YEASTS, V2, P282; SUOMALAINEN H, 1971, YEASTS, V2, P28; van Uden N, 1971, YEASTS, V2, P75; Videla H. A., 1971, EXPERIENTIA S, V18, P667; VIDELA HA, IN PRESS; WHITE J, 1954, YEAST TECHNOLOGY, P243; WHITE J, 1954, YEAST TECHNOLOGY, P63 | AG19: 15 | AH19: 29 | AI19: 29 | AJ19: 0 | AK19: 0 | AL19: JOHN WILEY & SONS INC | AM19: NEW YORK | AN19: 605 THIRD AVE, NEW YORK, NY 10158-0012 | AO19: 0006-3592 | AR19: BIOTECHNOL BIOENG | AS19: Biotechnol. Bioeng. | AU19: 1975 | AV19: 17 | AW19: 10 | BB19: 1529 | BC19: 1543 | BE19: 10.1002/bit.260171011 | BI19: 15 | BJ19: Biotechnology & Applied Microbiology | BK19: Biotechnology & Applied Microbiology | BL19: AX169 | BM19: WOS:A1975AX16900010 | BN19: 241440 | BR19: 43703
A20: 19 | B20: 10.1097/00010694-197501000-00011 | C20: J | D20: DEELMAN, JC | H20: DEELMAN, JC | K20: BACTERIAL SULFATE REDUCTION AFFECTING CARBONATE SEDIMENTS | L20: SOIL SCIENCE | O20: English | P20: Article | Y20: UNIV HEIDELBERG,MINERAL PETRO INST,LAB SEDIMENT FORSCH,BERLINR STR 19,6900 HEIDELBERG,FED REP GER | AF20: ALLEN RC, 1969, J SEDIMENT PETROL, V39, P136, DOI 10.1306/74D71BF9-2B21-11D7-8648000102C1865D; BAARS JK, 1930, THESIS MEINEMA; Baas-Becking L.G.M., 1960, J GEOL, V68, P243; Bavendamm W, 1932, ARCH MIKROBIOLOGIE, V3, P205; Beijerinck M.W., 1895, CENTRALBL BAKTERIO 2, P1; BERNER RA, 1969, MAR GEOL, V7, P253, DOI 10.1016/0025-3227(69)90011-5; BERNER RA, 1971, PRINCIPLES CHEMICAL; Beyerinck M. W., 1895, CENTRALBL BAKTERIO 2, V1, P104; BEYERINCK MW, 1895, CENTRAL BAKT, V1, P49; CONNELL WE, 1969, SOIL SCI SOC AM PRO, V33, P711, DOI 10.2136/sssaj1969.03615995003300050026x; CONNELL WE, 1968, SCIENCE, V159, P86, DOI 10.1126/science.159.3810.86; FRIEDMAN GM, 1972, AM ASSOC PETR GEOL B, V56, P1072; Gillespie LJ, 1920, SOIL SCI, V9, P199, DOI 10.1097/00010694-192004000-00001; HATHAWAY JC, 1969, SCIENCE, V165, P690, DOI 10.1126/science.165.3894.690; HEWITT LF, 1931, OXIDATION REDUCTION; Lalou C, 1957, J SEDIMENT PETROL, V27, P190; LECHAVELIER HA, 1971, MICROBES; Mansfield C. W., 1960, OXIDATION REDUCTION; MOLISH H, 1925, CENTRBL BAKT, V65, P130; Monaghan P, 1956, J SEDIMENT PETROL, V26, P111; NADSON G. A., 1928, ARCH HYDROBIOL, V19, P154; POP LJJ, 1936, THESIS LEIDEN; Potter MC, 1911, P R SOC LOND B-CONTA, V84, P260, DOI 10.1098/rspb.1911.0073; PRESLEY BJ, 1968, GEOCHIM COSMOCHIM AC, V32, P1037, DOI 10.1016/0016-7037(68)90106-3; Rittenberg SC, 1940, J MAR RES, V3, P191; STATSHCHUK MF, 1972, OXIDATION REDUCTION; SWEENEY RE, 1973, ECON GEOL, V68, P618, DOI 10.2113/gsecongeo.68.5.618; SZENTGYORGYI A, 1968, BIOELECTRONICS; VANDELDEN A, 1904, CENT BAKT INFEKT 2, V11, P81; VANDELDEN A, 1904, CENT BAKT INFEKT 2, V11, P113; WOLZOGENKUHR CAH, 1923, P KONINKL AKAD WETEN, V25, P188; ZoBell C.E., 1946, MARINE MICROBIOLOGY; Zobell C. E., 1938, J SEDIMENT PETROL, V8, P10 | AG20: 33 | AH20: 5 | AI20: 5 | AJ20: 0 | AK20: 0 | AL20: WILLIAMS & WILKINS | AM20: BALTIMORE | AN20: 351 WEST CAMDEN ST, BALTIMORE, MD 21201-2436 | AO20: 0038-075X | AR20: SOIL SCI | AS20: Soil Sci. | AU20: 1975 | AV20: 119 | AW20: 1 | BB20: 73 | BC20: 80 | BE20: 10.1097/00010694-197501000-00011 | BI20: 8 | BJ20: Soil Science | BK20: Agriculture | BL20: V8118 | BM20: WOS:A1975V811800010 | BR20: 43703
A21: 20 | B21: 10.1002/jobm.3630150705 | C21: J | D21: JACOB, HE; STUR, JK; MAREK, N | H21: JACOB, HE; STUR, JK; MAREK, N | K21: INTERPRETATION OF REDOX POTENTIAL OF BIOLOGICAL OBJECTS .7. DETERMINATION WITH DIFFERENT PLATINUM-ELECTRODES IN SOLUTIONS OF ELECTROLYTES | L21: ZEITSCHRIFT FUR ALLGEMEINE MIKROBIOLOGIE | O21: German | P21: Article | Y21: DAWB,ZENT INST MIKROBIOL & EXPTL THERAPIE,FORSCH ZENTRUM MOLEKULARBIOL & MED,BEUTHENBERG STR 11,JENA,GER DEM REP; MED UNIV SZEGED,INST MED CHEM,SZEGED,HUNGARY | AF21: CLARK LC, 1953, J APPL PHYSIOL, V6, P189; Clark W. M., 1960, OXIDATION REDUCTION; CLARK WM, 1920, P SOC AM BACTERIOL, V4, P2; GALGOCZY B, IN PRESS; Gillespie LJ, 1920, SOIL SCI, V9, P199, DOI 10.1097/00010694-192004000-00001; Hewitt L.F., 1950, OXIDATION REDUCTION; HONGO M, 1972, AGR BIOL CHEM TOKYO, V36, P273; HORN G, 1964, 3RD INT C POL SOUTH, P943; Jacob H. E., 1974, BIOTECHNOL BIOENG S, V4, P781; JACOB HE, 1967, Z ALLG MIKROBIOL, V7, P407, DOI 10.1002/jobm.3630070510; JACOB HE, 1965, Z ALLG MIKROBIOL, V5, P33, DOI 10.1002/jobm.3630050105; JACOB HE, 1971, Z ALLG MIKROBIOL, V11, P691, DOI 10.1002/jobm.3630110809; JACOB HE, 1970, PATHOL MICROBIOL, V36, P57, DOI 10.1159/000162420; LENGYEL Z, 1962, AEROB FERMENTACIOK O; MAREK N, 1966, ACTA BIOL ACAD SCI H, V16, P319; MAREK N, 1967, THEORETISCHE EXPTL U, V6, P223; MAREK N, 1967, STUDIA BIOPHYS, V3, P255; MATKOVICS B., 1959, SCHWEIZ ZEITSCHR ALLG PATH U BAKT, V22, P214; MICHAELIS L, 1933, OXYDATIONS REDUKTION; Potter MC, 1911, P R SOC LOND B-CONTA, V84, P260, DOI 10.1098/rspb.1911.0073; RABOTNOWA I, 1963, BEDEUTUNG PHYSIKALIS; SQUIRES RW, 1958, IND ENG CHEM, V50, P1263, DOI 10.1021/ie50585a032; TENGERDY RP, 1962, J BIOCH MICROBIOL TE, V3, P241 | AG21: 23 | AH21: 0 | AI21: 0 | AJ21: 0 | AK21: 0 | AL21: AKADEMIE VERLAG GMBH | AM21: BERLIN | AN21: MUHLENSTRASSE 33-34, D-13187 BERLIN, GERMANY | AO21: 0044-2208 | AR21: Z ALLG MIKROBIOL | AU21: 1975 | AV21: 15 | AW21: 7 | BB21: 513 | BC21: 522 | BE21: 10.1002/jobm.3630150705 | BI21: 10 | BJ21: Biotechnology & Applied Microbiology; Microbiology | BK21: Biotechnology & Applied Microbiology; Microbiology | BL21: BA967 | BM21: WOS:A1975BA96700004 | BN21: 1210352 | BR21: 43703
A22: 21 | C22: J | D22: VIDELA, HA; ARVIA, AJ | H22: VIDELA, HA; ARVIA, AJ | K22: STUDY ON BIOLOGICAL FUEL CELL COUPLED TO DISCONTINUOUS FERMENTATION PROCESS | L22: ANALES DE LA ASOCIACION QUIMICA ARGENTINA | O22: Spanish | P22: Article | Z22: VIDELA, HA (reprint author), UNIV NACL LA PLATA,FAC CIENCIAS EXACTAS,INST INVEST FISICOQUIM TEORICAS & APLICADAS,LA PLATA,ARGENTINA. | AF22: ALLEN MJ, 1966, BACTERIOL REV, V30, P80; ALLEN MJ, 1964, ELECTROCHIM ACTA, V9, P1423; BOCKRIS JOM, 1969, FUEL CELLS THEIR ELE, P612; CENEK M, 1968, CHEM LISTY, V62, P927; COHEN B, 1931, J BACTERIOL, V18, P21; ERTOLA R, 1967, IND QUIM, V25, P224; HEINEKEN FG, 1970, BIOTECHNOL BIOENG, V12, P145, DOI 10.1002/bit.260120113; JOHNSON MJ, 1967, BIOTECHNOL BIOENG, V9, P635; JOHNSON MJ, 1970, BIOTECHNOL BIOENG, V12, P145; LEWIS K, 1966, BACTERIOL REV, V30, P101; Potter MC, 1911, P R SOC LOND B-CONTA, V84, P260, DOI 10.1098/rspb.1911.0073; SHAW M, 1963, P ANN POWER SOURCES, V17, P53; Sisler F D, 1971, Prog Ind Microbiol, V9, P1; SOKATCH JR, 1969, BACTERIAL PHYSL META, P157; Videla H. A., 1971, EXPERIENTIA S, V18, P667; WANG DIC, 1968, CHEM ENG, V75, P99; YOUNG TG, 1966, BIOTECHNOL BIOENG, V8, P581, DOI 10.1002/bit.260080410; 1967, Patent No. 1062816 | AG22: 18 | AH22: 4 | AI22: 4 | AJ22: 0 | AK22: 0 | AL22: ASOC QUIMICA ARGENTINA | AM22: BUENOS AIRES | AN22: SANCHEZ DE BUSTAMANTE 1749, 1425 BUENOS AIRES, ARGENTINA | AO22: 0365-0375 | AR22: AN ASOC QUIM ARGENT | AS22: An. Asoc. Quim. Argent. | AU22: 1976 | AV22: 64 | AW22: 2 | BB22: 85 | BC22: 94 | BI22: 10 | BJ22: Chemistry, Multidisciplinary | BK22: Chemistry | BL22: EJ724 | BM22: WOS:A1976EJ72400002 | BR22: 43703
A23: 22 | B23: 10.1080/00021369.1979.10863776 | C23: J | D23: HONGO, M; IWAHARA, M | H23: HONGO, M; IWAHARA, M | K23: ELECTROCHEMICAL STUDIES ON FERMENTATION .1. APPLICATION OF ELECTRO-ENERGIZING METHOD TO L-GLUTAMIC ACID FERMENTATION | L23: AGRICULTURAL AND BIOLOGICAL CHEMISTRY | O23: English | P23: Article | Z23: HONGO, M (reprint author), KUMAMOTO UNIV,DEPT APPL MICROBIAL TECHNOL,KUMAMOTO 860,JAPAN. | AF23: Allen M. J., 1966, ELECTROCHIM ACTA, V11, P1503; ALLEN MJ, 1967, ELECTROCHIM ACTA, V12, P563, DOI 10.1016/0013-4686(67)80025-2; ALLEN MJ, 1967, ELECTROCHIM ACTA, V12, P569, DOI 10.1016/0013-4686(67)80026-4; ALLEN MJ, 1964, ELECTROCHIM ACTA, V9, P1429; ALLEN MJ, 1966, ELECTROCHIM ACTA, V11, P7; ALLEN MJ, 1966, ELECTROCHIM ACTA, V11, P15; ALLEN MJ, 1966, ELECTROCHIM ACTA, V11, P1; BERK RS, 1963, APPL MICROBIOL, V12, P10; Clark W. M., 1960, OXIDATION REDUCTION; Cohen B., 1931, J BACTERIOL, V21, P18; CONWAY EJ, 1955, BIOCHEM J, V61, P32, DOI 10.1042/bj0610032; DAVIS JB, 1962, SCIENCE, V137, P615, DOI 10.1126/science.137.3530.615; DELDUCA DG, 1963, DEV IND MICROBIOL, V4, P81; FEDOROV MV, 1950, DOKL AKAD NAUK SSSR+, V72, P1139; Friedemann TE, 1943, J BIOL CHEM, V147, P415; HANKE ME, 1943, ARCH BIOCHEM BIOPHYS, V2, P183; Hewitt L.F., 1950, OXIDATION REDUCTION; HIROSE Y, 1966, AGR BIOL CHEM TOKYO, V30, P49, DOI 10.1080/00021369.1966.10858554; HONGO M, 1972, AGR BIOL CHEM TOKYO, V36, P273; HONGO M, 1972, AGR BIOL CHEM TOKYO, V36, P269, DOI 10.1080/00021369.1972.10860244; HONGO M, 1972, AGR BIOL CHEM TOKYO, V36, P141, DOI 10.1080/00021369.1972.10860221; HONGO M, 1972, AGR BIOL CHEM TOKYO, V36, P279; HONGO M, 1973, Patent No. 33394; HONGO M, 1960, AMINO ACID, V2, P62; HONGO M, 1957, NIPPON NOGEIKAGAKU K, V31, P816; HONGO M, 1958, NIPPON NOGEIKAGAKU K, V32, pA113; HONGO M, 1968, ANNUAL M AGRICULTURA, P155; HONGO M, 1957, NIPPON NOGEI KAGAKU, V31, P735; HONGO M, 1975, HAKKOKIYOUKAISHI, V33, P398; HONGO M, 1972, Patent No. 15745; HONGO M, 1958, NIPPON NOGEIKAGAKU K, V32, pA101; HONGO M, 1958, NIPPON NOGEIKAGAKU K, V32, P29; HONGO M, 1958, NIPPON NOGEIKAGAKU K, V32, P155; HONGO M, 1957, NIPPON NOGIEKAKU KAI, V31, P731; HONGO M, 1957, NIPPON NOGEIKAGAKU K, V31, P811; HOSHINO K, 1943, NIPPON NOGEIKAGAKU K, V19, P405; HUANG SY, 1974, J FERMENT TECHNOL, V52, P818; ISHIZAKI A, 1974, AGR BIOL CHEM TOKYO, V38, P2399, DOI 10.1080/00021369.1974.10861537; ISHIZAKI A, 1974, AGRIC BIOL CHEM, V38, P2407; JOSLYN MA, 1949, IND ENG CHEM, V41, P587, DOI 10.1021/ie50471a031; JOSLYN MA, 1935, FRUITS PRODUCTS J, V20, P294; JOSLYN MA, 1935, FRUITS PRODUCTS J, V20, P277; JOSLYN MA, 1935, FRUITS PRODUCTS J, V20, P288; KARUBE I, 1978, ANNUAL M FERMENTATIO, P161; KLEBEL W, 1948, BRAUWISSENSCHAFT, V69, P215; KLUYVER AJ, 1937, ENZYMOL, V1, P1; KUBO H, 1947, SANKAKANGEN DENI; LANGLYKKE AF, 1948, IND ENG CHEM, V20, P1716; LEWIS K, 1966, BACTERIOL REV, V30, P101; MIKHLIN E D, 1954, Biokhimiia, V19, P549; MIYACHI N, 1961, NIPPON NOG KAG KAISH, V35, P1207; MIYACHI N, 1957, NIPPON NOGEIKAGAKU K, V31, P229; MIYACHI N, 1956, NIPPON NOGEIKAGAKU K, V30, P485; MIYACHI N, 1957, NIPPON NOGEIKAGAKU K, V31, P61; MIYACHI N, 1963, NIPPON NOGEIKAGAKU K, V37, P287; MIYACHI N, 1956, NIPPON NOGEIKAGAKU K, V30, P770; MIYACHI N, 1957, NIPPON NOGEIKAGAKU K, V31, P145; MIYACHI N, 1962, NIPPON NOGEIKAGAKU K, V36, P91; MIZUGUCHI J, 1964, KOGYO KAGAKU ZASSHI, V67, P410; MIZUGUCHI J, 1962, KOGYO KAGAKU ZASSHI, V65, P1606; MIZUGUCHI J, 1970, KOGYO KAGAKU ZASSHI, V73, P912; MIZUGUCHI J, 1968, KOGYO KAGAKU ZASSHI, V71, P640; MIZUGUCHI J, 1970, KOGYO KAGAKU ZASSHI, V73, P908; MIZUGUCHI J, 1967, KOGYO KAGAKU ZASSHI, V70, P296; MIZUGUCHI J, 1967, KOGYO KAGAKU ZASSHI, V70, P1072; PEEL JL, 1972, METHOD MICROBIOLOG B, V6, P14; Potter MC, 1911, P R SOC LOND B-CONTA, V84, P260, DOI 10.1098/rspb.1911.0073; RIPPON JW, 1968, APPL MICROBIOL, V16, P114; SADOFF HL, 1956, APPL MICROBIOL, V4, P164; SCHLEGEL HG, 1966, FERMENTATION ADV, P807; SHIIO I, 1959, J BIOCHEM-TOKYO, V46, P1597, DOI 10.1093/oxfordjournals.jbchem.a126957; SIEBEL FP, 1949, IND ENG CHEM, V27, P1042; SOMOGYI M, 1952, J BIOL CHEM, V195, P19; TAMURA G, 1952, J AGRIC CHEM SOC JAP, V26, P464; TANAKA M, 1967, HAKKO KENKYUSHO HOKO, V32, P55; VANHEES W, 1965, J ELECTROCHEM SOC, V112, P258, DOI 10.1149/1.2423519; WATANABE Y, 1960, NIPPON NOGEIKAGAKU K, V34, P620; WILLIAMS VR, 1947, J BIOL CHEM, V170, P399; WURMSER R, 1942, SEITAI SANKAKANGEN; YAMABE S, 1970, SEITAI SANKAKANGEN; YAMADA A, 1943, OSAKA IGAKU KAISHI, V42, P1820 | AG23: 81 | AH23: 50 | AI23: 52 | AJ23: 0 | AK23: 13 | AL23: JAPAN SOC BIOSCI BIOTECHN AGROCHEM | AM23: TOKYO | AN23: JAPAN ACAD SOC CTR BLDG, 2-4-6 YAYOI BUNKYO-KU, TOKYO 113, JAPAN | AO23: 0002-1369 | AR23: AGR BIOL CHEM TOKYO | AU23: 1979 | AV23: 43 | AW23: 10 | BB23: 2075 | BC23: 2081 | BE23: 10.1080/00021369.1979.10863776 | BI23: 7 | BJ23: Agronomy; Biochemistry & Molecular Biology | BK23: Agriculture; Biochemistry & Molecular Biology | BL23: HS206 | BM23: WOS:A1979HS20600010 | BR23: 43703
A24: 23 | C24: J | D24: SEIP, WF; EVANS, GL | H24: SEIP, WF; EVANS, GL | K24: ATMOSPHERIC ANALYSIS AND REDOX POTENTIALS OF CULTURE MEDIA IN THE GASPAK SYSTEM | L24: JOURNAL OF CLINICAL MICROBIOLOGY | O24: English | P24: Article | Y24: BECTON DICKINSON & CO,BBL MICROBIOL SYST,RES & DEV,COCKEYSVILLE,MD 21030 | AF24: ARANKI A, 1969, APPL MICROBIOL, V17, P568; BARTLETT RC, 1974, CUMITECH 1 BLOOD CUL; BOKKENHEUSER V, 1969, HEALTH LAB SCI, V6, P162; BREWER JH, 1965, SCIENCE, V147, P1033, DOI 10.1126/science.147.3661.1033-a; BREWER JH, 1966, APPL MICROBIOL, V14, P985; BREWER JH, 1966, APPL MICROBIOL, V14, P135; CARLSSON J, 1978, APPL ENVIRON MICROB, V36, P223; CLARKE WM, 1960, OXIDATION REDUCTION, P131; COLLEE JG, 1972, J APPL BACTERIOL, V35, P71, DOI 10.1111/j.1365-2672.1972.tb03675.x; ELLNER PD, 1973, APPL MICROBIOL, V26, P904; ERICSSON HM, 1971, ACTA PATHOL M B S217, P34; FERGUSON IR, 1975, J APPL BACTERIOL, V39, P167, DOI 10.1111/j.1365-2672.1975.tb00558.x; Gillespie RWH, 1938, J BACTERIOL, V36, P605; Holdeman LV, 1977, ANAEROBE LABORATORY; HOLLAND JW, 1977, J CLIN MICROBIOL, V5, P20; KILLGORE GE, 1973, AM J CLIN PATHOL, V59, P552; LOESCHE WJ, 1969, APPL MICROBIOL, V18, P723; MCGARRITY RJ, 1973, IN VITRO, V9, P17; MCMINN MT, 1970, APPL MICROBIOL, V19, P207; MOORE WEC, 1969, J INFECT DIS, V119, P641, DOI 10.1093/infdis/119.6.641; ONDERDONK AB, 1976, APPL ENVIRON MICROB, V31, P168; Potter MC, 1911, P R SOC LOND B-CONTA, V84, P260, DOI 10.1098/rspb.1911.0073; ROLFE RD, 1978, APPL ENVIRON MICROB, V36, P306; STALONS DR, 1974, APPL MICROBIOL, V27, P1098; Sutter V L, 1973, Prog Clin Pathol, V5, P219; TABATABAI LB, 1970, APPL MICROBIOL, V20, P441; WALDEN WC, 1975, APPL MICROBIOL, V30, P781; WATT B, 1973, J MED MICROBIOL, V6, P307, DOI 10.1099/00222615-6-3-307; WESTCOTT CC, 1976, 952EC766T BECKM INST; WILLIS AT, 1977, ANAEROBIC BACTERIOLO, P9 | AG24: 30 | AH24: 52 | AI24: 54 | AJ24: 0 | AK24: 1 | AL24: AMER SOC MICROBIOLOGY | AM24: WASHINGTON | AN24: 1325 MASSACHUSETTS AVENUE, NW, WASHINGTON, DC 20005-4171 | AO24: 0095-1137 | AR24: J CLIN MICROBIOL | AS24: J. Clin. Microbiol. | AU24: 1980 | AV24: 11 | AW24: 3 | BB24: 226 | BC24: 233 | BI24: 8 | BJ24: Microbiology | BK24: Microbiology | BL24: JK827 | BM24: WOS:A1980JK82700006 | BN24: 6769944 | BR24: 43703
A25: 24 | C25: J | D25: GOVIL, G; SARAN, A | H25: GOVIL, G; SARAN, A | K25: BIOCHEMICAL FUEL-CELLS | L25: JOURNAL OF THE INDIAN CHEMICAL SOCIETY | O25: English | P25: Article | Z25: GOVIL, G (reprint author), TATA INST FUNDAMENTAL RES,BIOCHEM FUEL CELL PROJECT,HOMI BHABHA RD,BOMBAY 400005,INDIA. | AF25: BEREZIN IV, 1979, APPLIED BIOCH BIOENG, V2, P259; BLANCHARD GC, 1971, J ELECTROCHEM SOC, V118, P1232, DOI 10.1149/1.2408290; Cohen B., 1931, J BACTERIOL, V21, P18; COLICHMAN EL, 1963, P IEEE, P812; DAVIS JB, 1962, SCIENCE, V137, P615, DOI 10.1126/science.137.3530.615; HOWARD J, 1971, NEW SCI, V48, P528; LEWIS K, 1966, BACTERIOL REV, V30, P101; PHADKE RS, UNPUB; Potter MC, 1911, P R SOC LOND B-CONTA, V84, P260, DOI 10.1098/rspb.1911.0073; Sisler F D, 1971, Prog Ind Microbiol, V9, P1; SISLER FD, 1961, NEW SCIENTIST, V12, P110; VANHEES W, 1965, J ELECTROCHEM SOC, V112, P258, DOI 10.1149/1.2423519; WILSON BJ, 1963, NRL5998 REP; WINGARD LB, 1971, BIOTECHNOL BIOENG, V13, P629, DOI 10.1002/bit.260130504; 1980, B INDIAN PHYSICS ASS, V11 | AG25: 15 | AH25: 7 | AI25: 7 | AJ25: 0 | AK25: 0 | AL25: INDIAN CHEMICAL SOC | AM25: CALCUTTA | AN25: 92 ACHARYA PRAFULLA CHANDRA RD ATTN:DR INDRAJIT KAR/EXEC SEC, CALCUTTA 700009, INDIA | AO25: 0019-4522 | AR25: J INDIAN CHEM SOC | AS25: J. Indian Chem. Soc. | AU25: 1982 | AV25: 59 | AW25: 43476 | BB25: 1226 | BC25: 1228 | BI25: 3 | BJ25: Chemistry, Multidisciplinary | BK25: Chemistry | BL25: RB291 | BM25: WOS:A1982RB29100006 | BR25: 43703
A26: 25 | B26: 10.1016/0300-9467(86)80023-5 | C26: J | D26: YUE, PL; LOWTHER, K | H26: YUE, PL; LOWTHER, K | K26: ENZYMATIC OXIDATION OF C1 COMPOUNDS IN A BIOCHEMICAL FUEL-CELL | L26: CHEMICAL ENGINEERING JOURNAL AND THE BIOCHEMICAL ENGINEERING JOURNAL | O26: English | P26: Article | Z26: YUE, PL (reprint author), UNIV BATH,SCH CHEM ENGN,CLAVERTON DOWN,BATH BA2 7AY,AVON,ENGLAND. | AF26: ASTON WJ, 1984, BIOTECHNOL GENET ENG, V1, P89, DOI 10.1080/02648725.1984.10647782; DAVIS G, 1983, ENZYME MICROB TECH, V5, P383, DOI 10.1016/0141-0229(83)90013-3; Fickett A. P., 1978, Scientific American, V239, P54; Grove W. R., 1839, PHILOS MAG, P127, DOI DOI 10.1080/14786443908649684; HELMUTH NA, 1967, Patent No. 3340094; HIGGINS IJ, 1980, HYDROCARBONS BIOTECH, P181; HILL HAO, 1981, PHILOS T R SOC A, V302, P267, DOI 10.1098/rsta.1981.0166; KARUBE I, 1981, ANN NY ACAD SCI, V369, P91; PLOTKIN EV, 1981, BIOTECHNOL LETT, V3, P187; Potter MC, 1911, P R SOC LOND B-CONTA, V84, P260, DOI 10.1098/rspb.1911.0073; Sisler F. D., 1969, Patent, Patent No. [3,477,879, 3477879]; TOFIELD BC, 1981, APPL ENERG, V8, P89, DOI 10.1016/0306-2619(81)90014-3; Turner APF, 1982, BIOTECHNOL BIOENG S, V12, P401; WARBURG O, 1957, METHOD ENZYMOL, V3, P451; Wingard L B Jr, 1978, Hindustan Antibiot Bull, V20, P109; WINGARD LB, 1982, ENZYME MICROB TECH, V4, P137, DOI 10.1016/0141-0229(82)90104-1 | AG26: 16 | AH26: 10 | AI26: 10 | AJ26: 0 | AK26: 0 | AL26: ELSEVIER SCIENCE SA LAUSANNE | AM26: LAUSANNE 1 | AN26: PO BOX 564, 1001 LAUSANNE 1, SWITZERLAND | AO26: 0923-0467 | AR26: CHEM ENG J BIOCH ENG | AS26: Chem. Eng. J. Biochem. Eng. J. | AT26: DEC | AU26: 1986 | AV26: 33 | AW26: 3 | BB26: B69 | BC26: B77 | BE26: 10.1016/0300-9467(86)80023-5 | BI26: 9 | BJ26: Engineering, Chemical | BK26: Engineering | BL26: F4449 | BM26: WOS:A1986F444900010 | BR26: 43703
