Workbook

Sheet 1. DF_continuous_pH7_1
B1: Succinate | C1: EtOH | D1: Formate | E1: Acétate | F1: 1,3-propanediol | G1: Propionate | H1: isobutyrate | I1: Ethanol | J1: Butyrate | K1: isovalérate | L1: Butanol | M1: H2 | N1: Caproate | Z1: g TS in | AA1: =AC1/0.97 -> 30.927835 | AB1: g VS in | AC1: 30 | AG1: 30 | AH1: VS/L | AJ1: 2 | AK1: L
B2: 0.948 | C2: 2.0842 | D2: 1.39 | E2: 1.067 | F2: 1.26 | G2: 1.51 | H2: 1.818 | I2: 2.0842 | J2: 1.818 | K2: 2.0326 | L2: 2.59 | M2: 8 | N2: 2.2 | AA2: =AC2/0.97 -> 46.391753 | AC2: 45 | AF2: OLR30 | AG2: =30*1.28 -> 38.4 | AH2: g COD/L | AJ2: CODin - I | AK2: =AG1*AJ1*1.28 -> 76.8 | AL2: g COD
AA3: =AC3/0.97 -> 46.391753 | AC3: 45 | AF3: OLR45 | AG3: =45*1.28 -> 57.6 | AJ3: CODin - II | AK3: =45*AJ1*1.28 -> 115.2 | AL3: g COD
AF4: OLR60 | AG4: =45*1.28 -> 57.6 | AH4: higher Q | AJ4: CODin - III
F5: headpsace | K5: VFAs | Z5: VFAs-COD | AW5: Profile (%COD)
C6: Days | D6: Date | E6: Time | F6: CO2 | G6: H2 | H6: O2 | I6: N2 | J6: CH4 | K6: C2 | L6: C3 | M6: IC4 | N6: C4 | O6: IC5 | P6: C5 | Q6: IC6 | R6: C6 | S6: Lactate | T6: Succinate | U6: Formate | V6: EtOH | W6: Total met | X6: Total VFAs | Y6: Days | Z6: C2 | AA6: C3 | AB6: IC4 | AC6: C4 | AD6: IC5 | AE6: C5 | AF6: IC6 | AG6: C6 | AH6: Lactate | AI6: Succinate | AJ6: Formate | AK6: EtOH | AL6: COD-VFAs | AM6: COD-VFAs/CODin | AN6: tCOD (g/L) | AO6: sCOD (g/L) | AP6: VFAs-COD/sCOD | AQ6: sCOD/tCOD | AR6: COD removal (%) | AS6: g met/g Vsin | AT6: g VFAs/g VS | AU6: g VFAs/g Tsin | AV6: g COD-met/Ld | AW6: C2 | AX6: C3 | AY6: IC4 | AZ6: C4 | BA6: IC5 | BB6: C5 | BC6: IC6 | BD6: C6 | BE6: Lactate | BF6: Succinate | BG6: Formate | BH6: EtOH
A7: OLR 30 g VS/Ld | C7: 0 | D7: 44740 | Y7: =C7 -> 0
B8: =D8-D7 -> 1 | C8: =C7+B8 -> 1 | D8: 44741 | E8: 0.41666667 | K8: 3.63 | L8: 3.501 | M8: 0.044 | N8: 0.699 | O8: 0.029 | P8: 0.075 | Q8: 0 | R8: 0 | S8: 0 | T8: 0 | U8: 0 | V8: 0 | W8: =SUM(K8:R8) -> 7.978 | X8: =SUM(K8:R8) -> 7.978 | Y8: =C8 -> 1 | Z8: =K8*$E$2 -> 3.87321 | AA8: =L8*$G$2 -> 5.28651 | AB8: =M8*$H$2 -> 0.079992 | AC8: =N8*$J$2 -> 1.270782 | AD8: =O8*$K$2 -> 0.0589454 | AE8: =P8*$K$2 -> 0.152445 | AF8: =Q8*$N$2 -> 0 | AG8: =R8*$N$2 -> 0 | AH8: =S8*1.067 -> 0 | AI8: =T8*$B$2 -> 0 | AJ8: =U8*$D$2 -> 0 | AK8: =V8*$C$2 -> 0 | AL8: =SUM(Z8:AK8) -> 10.721884 | AM8: =(AL8/($AG$2))*100 -> 27.921574 | AP8: =AL8/AO8*100 -> #DIV/0! | AQ8: =AO8/AN8 -> #DIV/0! | AR8: =($AG$2-AN8)/$AG$2*100 -> 100 | AS8: =((W8)/$AC$1) -> 0.26593333 | AT8: =((X8)/$AC$1) -> 0.26593333 | AU8: =X8/$AA$1 -> 0.25795533 | AV8: =AL8/1 -> 10.721884 | AW8: =Z8/$AL8*100 -> 36.12434 | AX8: =AA8/$AL8*100 -> 49.305792 | AY8: =AB8/$AL8*100 -> 0.74606288 | AZ8: =AC8/$AL8*100 -> 11.852226 | BA8: =AD8/$AL8*100 -> 0.54976717 | BB8: =AE8/$AL8*100 -> 1.4218116 | BC8: =AF8/$AL8*100 -> 0 | BD8: =AG8/$AL8*100 -> 0 | ... BH8: =AK8/$AL8*100 -> 0
B9: =D9-D8 -> 1 | C9: =C8+B9 -> 2 | D9: 44742 | E9: 0.45833333 | F9: 28.26 | G9: 36.06 | H9: 3.55 | I9: 32.12 | K9: 5.117 | L9: 3.878 | M9: 0.075 | N9: 1.131 | O9: 0.07 | P9: 0.085 | Q9: 0.028 | R9: 0 | S9: 0 | T9: 0.8298 | U9: 0 | V9: 0 | W9: =SUM(K9:T9) -> 11.2138 | X9: =SUM(K9:R9) -> 10.384 | Y9: =C9 -> 2 | Z9: =K9*$E$2 -> 5.459839 | AA9: =L9*$G$2 -> 5.85578 | AB9: =M9*$H$2 -> 0.13635 | AC9: =N9*$J$2 -> 2.056158 | AD9: =O9*$K$2 -> 0.142282 | AE9: =P9*$K$2 -> 0.172771 | AF9: =Q9*$N$2 -> 0.0616 | AG9: =R9*$N$2 -> 0 | AH9: =S9*1.067 -> 0 | AI9: =T9*$B$2 -> 0.7866504 | AJ9: =U9*$D$2 -> 0 | AK9: =V9*$C$2 -> 0 | AL9: =SUM(Z9:AK9) -> 14.67143 | AM9: =(AL9/($AG$2))*100 -> 38.20685 | AP9: =AL9/AO9*100 -> #DIV/0! | AQ9: =AO9/AN9 -> #DIV/0! | AR9: =($AG$2-AN9)/$AG$2*100 -> 100 | AS9: =((W9)/$AC$1) -> 0.37379333 | AT9: =((X9)/$AC$1) -> 0.34613333 | AU9: =X9/$AA$1 -> 0.33574933 | AV9: =AL9/1 -> 14.67143 | AW9: =Z9/$AL9*100 -> 37.214088 | AX9: =AA9/$AL9*100 -> 39.912809 | AY9: =AB9/$AL9*100 -> 0.92935724 | AZ9: =AC9/$AL9*100 -> 14.014707 | BA9: =AD9/$AL9*100 -> 0.96978956 | BB9: =AE9/$AL9*100 -> 1.1776016 | BC9: =AF9/$AL9*100 -> 0.41986363 | BD9: =AG9/$AL9*100 -> 0 | ... BH9: =AK9/$AL9*100 -> 0
B10: =D10-D9 -> 1 | C10: =C9+B10 -> 3 | D10: 44743 | E10: 0.5 | F10: 26.58 | G10: 43.17 | H10: 4.9 | I10: 25.34 | K10: 5.371 | L10: 3.144 | M10: 0.086 | N10: 1.275 | O10: 0.08 | P10: 0.088 | Q10: 0.046 | R10: 0 | S10: 0 | T10: 1.473 | U10: 0 | V10: 0.8442 | W10: =SUM(K10:V10) -> 12.4072 | X10: =SUM(K10:R10) -> 10.09 | Y10: =C10 -> 3 | Z10: =K10*$E$2 -> 5.730857 | AA10: =L10*$G$2 -> 4.74744 | AB10: =M10*$H$2 -> 0.156348 | AC10: =N10*$J$2 -> 2.31795 | AD10: =O10*$K$2 -> 0.162608 | AE10: =P10*$K$2 -> 0.1788688 | AF10: =Q10*$N$2 -> 0.1012 | AG10: =R10*$N$2 -> 0 | AH10: =S10*1.067 -> 0 | AI10: =T10*$B$2 -> 1.396404 | AJ10: =U10*$D$2 -> 0 | AK10: =V10*$C$2 -> 1.7594816 | AL10: =SUM(Z10:AK10) -> 16.551157 | AM10: =(AL10/($AG$2))*100 -> 43.101973 | AP10: =AL10/AO10*100 -> #DIV/0! | AQ10: =AO10/AN10 -> #DIV/0! | AR10: =($AG$2-AN10)/$AG$2*100 -> 100 | AS10: =((W10)/$AC$1) -> 0.41357333 | AT10: =((X10)/$AC$1) -> 0.33633333 | AU10: =X10/$AA$1 -> 0.32624333 | AV10: =AL10/1 -> 16.551157 | AW10: =Z10/$AL10*100 -> 34.625113 | AX10: =AA10/$AL10*100 -> 28.683432 | AY10: =AB10/$AL10*100 -> 0.94463484 | AZ10: =AC10/$AL10*100 -> 14.004761 | BA10: =AD10/$AL10*100 -> 0.98245697 | BB10: =AE10/$AL10*100 -> 1.0807027 | BC10: =AF10/$AL10*100 -> 0.6114376 | BD10: =AG10/$AL10*100 -> 0 | ... BH10: =AK10/$AL10*100 -> 10.630566
B11: =D11-D10 -> 3 | C11: =C10+B11 -> 6 | D11: 44746 | E11: 0.5 | K11: 5.249 | L11: 2.106 | M11: 0.078 | N11: 1.245 | O11: 0.054 | P11: 0.09 | Q11: 0.08 | R11: 0.042 | S11: 0 | T11: 1.752 | U11: 0.546 | V11: 1.201 | W11: =SUM(K11:V11) -> 12.443 | X11: =SUM(K11:R11) -> 8.944 | Y11: =C11 -> 6 | Z11: =K11*$E$2 -> 5.600683 | AA11: =L11*$G$2 -> 3.18006 | AB11: =M11*$H$2 -> 0.141804 | AC11: =N11*$J$2 -> 2.26341 | AD11: =O11*$K$2 -> 0.1097604 | AE11: =P11*$K$2 -> 0.182934 | AF11: =Q11*$N$2 -> 0.176 | AG11: =R11*$N$2 -> 0.0924 | AH11: =S11*1.067 -> 0 | AI11: =T11*$B$2 -> 1.660896 | AJ11: =U11*$D$2 -> 0.75894 | AK11: =V11*$C$2 -> 2.5031242 | AL11: =SUM(Z11:AK11) -> 16.670012 | AM11: =(AL11/($AG$2))*100 -> 43.411489 | AP11: =AL11/AO11*100 -> #DIV/0! | AQ11: =AO11/AN11 -> #DIV/0! | AR11: =($AG$2-AN11)/$AG$2*100 -> 100 | AS11: =((W11)/$AC$1) -> 0.41476667 | AT11: =((X11)/$AC$1) -> 0.29813333 | AU11: =X11/$AA$1 -> 0.28918933 | AV11: =AL11/1 -> 16.670012 | AW11: =Z11/$AL11*100 -> 33.597355 | AX11: =AA11/$AL11*100 -> 19.076531 | AY11: =AB11/$AL11*100 -> 0.85065328 | AZ11: =AC11/$AL11*100 -> 13.577735 | BA11: =AD11/$AL11*100 -> 0.65843026 | BB11: =AE11/$AL11*100 -> 1.0973838 | BC11: =AF11/$AL11*100 -> 1.0557881 | BD11: =AG11/$AL11*100 -> 0.55428876 | ... BH11: =AK11/$AL11*100 -> 15.015732
B12: =D12-D11 -> 1 | C12: =C11+B12 -> 7 | D12: 44747 | E12: 0.5 | F12: 29.92 | G12: 63.12 | H12: 0 | I12: 6.97 | K12: 5.666 | L12: 2.176 | M12: 0.07 | N12: 1.321 | O12: 0.055 | P12: 0.092 | Q12: 0.074 | R12: 0.038 | S12: 0 | T12: 1.532 | U12: 0.549 | V12: 1.195 | W12: =SUM(K12:V12) -> 12.768 | X12: =SUM(K12:R12) -> 9.492 | Y12: =C12 -> 7 | Z12: =K12*$E$2 -> 6.045622 | AA12: =L12*$G$2 -> 3.28576 | AB12: =M12*$H$2 -> 0.12726 | AC12: =N12*$J$2 -> 2.401578 | AD12: =O12*$K$2 -> 0.111793 | AE12: =P12*$K$2 -> 0.1869992 | AF12: =Q12*$N$2 -> 0.1628 | AG12: =R12*$N$2 -> 0.0836 | AH12: =S12*1.067 -> 0 | AI12: =T12*$B$2 -> 1.452336 | AJ12: =U12*$D$2 -> 0.76311 | AK12: =V12*$C$2 -> 2.490619 | AL12: =SUM(Z12:AK12) -> 17.111477 | AM12: =(AL12/($AG$2))*100 -> 44.561139 | AP12: =AL12/AO12*100 -> #DIV/0! | AQ12: =AO12/AN12 -> #DIV/0! | AR12: =($AG$2-AN12)/$AG$2*100 -> 100 | AS12: =((W12)/$AC$1) -> 0.4256 | AT12: =((X12)/$AC$1) -> 0.3164 | AU12: =X12/$AA$1 -> 0.306908 | AV12: =AL12/1 -> 17.111477 | AW12: =Z12/$AL12*100 -> 35.330801 | AX12: =AA12/$AL12*100 -> 19.202083 | AY12: =AB12/$AL12*100 -> 0.74371136 | AZ12: =AC12/$AL12*100 -> 14.034896 | BA12: =AD12/$AL12*100 -> 0.65332174 | BB12: =AE12/$AL12*100 -> 1.0928291 | BC12: =AF12/$AL12*100 -> 0.95140822 | BD12: =AG12/$AL12*100 -> 0.48856098 | ... BH12: =AK12/$AL12*100 -> 14.555254
B13: =D13-D12 -> 1 | C13: =C12+B13 -> 8 | D13: 44748 | E13: 0.5 | F13: 26.84 | G13: 65.96 | H13: 0 | I13: 7.2 | K13: 5.003 | L13: 1.848 | M13: 0.055 | N13: 1.477 | O13: 0.043 | P13: 0.098 | Q13: 0.059 | R13: 0.046 | S13: 0 | T13: 1.5886286 | U13: 0.49191429 | V13: 1.4042571 | W13: =SUM(K13:V13) -> 12.1138 | X13: =SUM(K13:R13) -> 8.629 | Y13: =C13 -> 8 | Z13: =K13*$E$2 -> 5.338201 | AA13: =L13*$G$2 -> 2.79048 | AB13: =M13*$H$2 -> 0.09999 | AC13: =N13*$J$2 -> 2.685186 | AD13: =O13*$K$2 -> 0.0874018 | AE13: =P13*$K$2 -> 0.1991948 | AF13: =Q13*$N$2 -> 0.1298 | AG13: =R13*$N$2 -> 0.1012 | AH13: =S13*1.067 -> 0 | AI13: =T13*$B$2 -> 1.5060199 | AJ13: =U13*$D$2 -> 0.68376086 | AK13: =V13*$C$2 -> 2.9267527 | AL13: =SUM(Z13:AK13) -> 16.547987 | AM13: =(AL13/($AG$2))*100 -> 43.093716 | AN13: =634*40/1000 -> 25.36 | AO13: =833*20/1000 -> 16.66 | AP13: =AL13/AO13*100 -> 99.327654 | AQ13: =AO13/AN13 -> 0.65694006 | AR13: =($AG$2-AN13)/$AG$2*100 -> 33.958333 | AS13: =((W13)/$AC$1) -> 0.40379333 | AT13: =((X13)/$AC$1) -> 0.28763333 | AU13: =X13/$AA$1 -> 0.27900433 | AV13: =AL13/1 -> 16.547987 | AW13: =Z13/$AL13*100 -> 32.258914 | AX13: =AA13/$AL13*100 -> 16.862957 | AY13: =AB13/$AL13*100 -> 0.60424268 | AZ13: =AC13/$AL13*100 -> 16.226662 | BA13: =AD13/$AL13*100 -> 0.52817179 | BB13: =AE13/$AL13*100 -> 1.2037404 | BC13: =AF13/$AL13*100 -> 0.78438543 | BD13: =AG13/$AL13*100 -> 0.61155474 | ... BH13: =AK13/$AL13*100 -> 17.686458
B14: =D14-D13 -> 1 | C14: =C13+B14 -> 9 | D14: 44749 | E14: 0.5 | F14: 20.98 | G14: 52.56 | H14: 4.67 | I14: 21.8 | K14: 4.946 | L14: 1.776 | M14: 0.068 | N14: 1.596 | O14: 0.061 | P14: 0.1 | Q14: 0.049 | R14: 0.042 | S14: 0.623 | T14: 1.8920571 | U14: 0.873 | V14: 1.2255429 | W14: =SUM(K14:V14) -> 13.2516 | X14: =SUM(K14:R14) -> 8.638 | Y14: =C14 -> 9 | Z14: =K14*$E$2 -> 5.277382 | AA14: =L14*$G$2 -> 2.68176 | AB14: =M14*$H$2 -> 0.123624 | AC14: =N14*$J$2 -> 2.901528 | AD14: =O14*$K$2 -> 0.1239886 | AE14: =P14*$K$2 -> 0.20326 | AF14: =Q14*$N$2 -> 0.1078 | AG14: =R14*$N$2 -> 0.0924 | AH14: =S14*1.067 -> 0.664741 | AI14: =T14*$B$2 -> 1.7936702 | AJ14: =U14*$D$2 -> 1.21347 | AK14: =V14*$C$2 -> 2.5542764 | AL14: =SUM(Z14:AK14) -> 17.7379 | AM14: =(AL14/($AG$2))*100 -> 46.192448 | AN14: =648*40/1000 -> 25.92 | AO14: =842*20/1000 -> 16.84 | AP14: =AL14/AO14*100 -> 105.33195 | AQ14: =AO14/AN14 -> 0.64969136 | AR14: =($AG$2-AN14)/$AG$2*100 -> 32.5 | AS14: =((W14)/$AC$1) -> 0.44172 | AT14: =((X14)/$AC$1) -> 0.28793333 | AU14: =X14/$AA$1 -> 0.27929533 | AV14: =AL14/1 -> 17.7379 | AW14: =Z14/$AL14*100 -> 29.752011 | AX14: =AA14/$AL14*100 -> 15.118813 | AY14: =AB14/$AL14*100 -> 0.69694833 | AZ14: =AC14/$AL14*100 -> 16.357787 | BA14: =AD14/$AL14*100 -> 0.69900382 | BB14: =AE14/$AL14*100 -> 1.1459079 | BC14: =AF14/$AL14*100 -> 0.60773823 | BD14: =AG14/$AL14*100 -> 0.52091848 | ... BH14: =AK14/$AL14*100 -> 14.400106
B15: =D15-D14 -> 1 | C15: =C14+B15 -> 10 | D15: 44750 | E15: 0.5 | F15: 26.61 | G15: 64.15 | H15: 0.18 | I15: 9.04 | J15: 0.01 | K15: 4.853 | L15: 1.664 | M15: 0.071 | N15: 1.79 | O15: 0.068 | P15: 0.093 | Q15: 0.037 | R15: 0.034 | S15: 0.705 | T15: 1.9944 | U15: 0.99591429 | V15: 1.2283714 | W15: =SUM(K15:V15) -> 13.533686 | X15: =SUM(K15:R15) -> 8.61 | Y15: =C15 -> 10 | Z15: =K15*$E$2 -> 5.178151 | AA15: =L15*$G$2 -> 2.51264 | AB15: =M15*$H$2 -> 0.129078 | AC15: =N15*$J$2 -> 3.25422 | AD15: =O15*$K$2 -> 0.1382168 | AE15: =P15*$K$2 -> 0.1890318 | AF15: =Q15*$N$2 -> 0.0814 | AG15: =R15*$N$2 -> 0.0748 | AH15: =S15*1.067 -> 0.752235 | AI15: =T15*$B$2 -> 1.8906912 | AJ15: =U15*$D$2 -> 1.3843209 | AK15: =V15*$C$2 -> 2.5601717 | AL15: =SUM(Z15:AK15) -> 18.144956 | AM15: =(AL15/($AG$2))*100 -> 47.252491 | AN15: =659*40/1000 -> 26.36 | AO15: =849*20/1000 -> 16.98 | AP15: =AL15/AO15*100 -> 106.86076 | AQ15: =AO15/AN15 -> 0.64415781 | AR15: =($AG$2-AN15)/$AG$2*100 -> 31.354167 | AS15: =((W15)/$AC$1) -> 0.45112286 | AT15: =((X15)/$AC$1) -> 0.287 | AU15: =X15/$AA$1 -> 0.27839 | AV15: =AL15/1 -> 18.144956 | AW15: =Z15/$AL15*100 -> 28.537688 | AX15: =AA15/$AL15*100 -> 13.847595 | AY15: =AB15/$AL15*100 -> 0.71137123 | AZ15: =AC15/$AL15*100 -> 17.934571 | BA15: =AD15/$AL15*100 -> 0.76173674 | BB15: =AE15/$AL15*100 -> 1.041787 | BC15: =AF15/$AL15*100 -> 0.44860951 | BD15: =AG15/$AL15*100 -> 0.41223577 | ... BH15: =AK15/$AL15*100 -> 14.10955
B16: =D16-D15 -> 3 | C16: =C15+B16 -> 13 | D16: 44753 | E16: 0.5 | F16: 35.94 | G16: 45.91 | I16: 18.11 | J16: 0.04 | K16: 5.843 | L16: 2.203 | M16: 0.097 | N16: 2.325 | O16: 0.08 | P16: 0.244 | Q16: 0.033 | R16: 0.158 | S16: 0 | T16: 2.2608 | U16: 0.57882857 | V16: 0 | W16: =SUM(K16:V16) -> 13.822629 | X16: =SUM(K16:R16) -> 10.983 | Y16: =C16 -> 13 | Z16: =K16*$E$2 -> 6.234481 | AA16: =L16*$G$2 -> 3.32653 | AB16: =M16*$H$2 -> 0.176346 | AC16: =N16*$J$2 -> 4.22685 | AD16: =O16*$K$2 -> 0.162608 | AE16: =P16*$K$2 -> 0.4959544 | AF16: =Q16*$N$2 -> 0.0726 | AG16: =R16*$N$2 -> 0.3476 | AH16: =S16*1.067 -> 0 | AI16: =T16*$B$2 -> 2.1432384 | AJ16: =U16*$D$2 -> 0.80457171 | AK16: =V16*$C$2 -> 0 | AL16: =SUM(Z16:AK16) -> 17.99078 | AM16: =(AL16/($AG$2))*100 -> 46.850988 | AN16: =773*40/1000 -> 30.92 | AO16: =912*20/1000 -> 18.24 | AP16: =AL16/AO16*100 -> 98.63366 | AQ16: =AO16/AN16 -> 0.58990944 | AR16: =($AG$2-AN16)/$AG$2*100 -> 19.479167 | AS16: =((W16)/$AC$1) -> 0.46075429 | AT16: =((X16)/$AC$1) -> 0.3661 | AU16: =X16/$AA$1 -> 0.355117 | AV16: =AL16/1 -> 17.99078 | AW16: =Z16/$AL16*100 -> 34.653757 | AX16: =AA16/$AL16*100 -> 18.490194 | AY16: =AB16/$AL16*100 -> 0.98020211 | AZ16: =AC16/$AL16*100 -> 23.494535 | BA16: =AD16/$AL16*100 -> 0.90384077 | BB16: =AE16/$AL16*100 -> 2.7567143 | BC16: =AF16/$AL16*100 -> 0.40354005 | BD16: =AG16/$AL16*100 -> 1.9321008 | ... BH16: =AK16/$AL16*100 -> 0
B17: =D17-D16 -> 1 | C17: =C16+B17 -> 14 | D17: 44754 | E17: 0.5 | F17: 25 | G17: 35.36 | H17: 4.86 | I17: 34.73 | J17: 0.05 | K17: 5.055 | L17: 1.999 | M17: 0.089 | N17: 2.562 | O17: 0.089 | P17: 0.26 | Q17: 0.019 | R17: 0.237 | S17: 0.084857143 | T17: 1.9581429 | U17: 0.85294286 | V17: 0 | W17: =SUM(K17:V17) -> 13.205943 | X17: =SUM(K17:R17) -> 10.31 | Y17: =C17 -> 14 | Z17: =K17*$E$2 -> 5.393685 | AA17: =L17*$G$2 -> 3.01849 | AB17: =M17*$H$2 -> 0.161802 | AC17: =N17*$J$2 -> 4.657716 | AD17: =O17*$K$2 -> 0.1809014 | AE17: =P17*$K$2 -> 0.528476 | AF17: =Q17*$N$2 -> 0.0418 | AG17: =R17*$N$2 -> 0.5214 | AH17: =T17*1.067 -> 2.0893384 | AI17: =U16*$B$2 -> 0.54872949 | AJ17: =U17*$D$2 -> 1.1855906 | AK17: =V17*$C$2 -> 0 | AL17: =SUM(Z17:AK17) -> 18.327929 | AM17: =(AL17/($AG$2))*100 -> 47.728981 | AN17: =719*40/1000 -> 28.76 | AO17: =853*20/1000 -> 17.06 | AP17: =AL17/AO17*100 -> 107.43217 | AQ17: =AO17/AN17 -> 0.59318498 | AR17: =($AG$2-AN17)/$AG$2*100 -> 25.104167 | AS17: =((W17)/$AC$1) -> 0.4401981 | AT17: =((X17)/$AC$1) -> 0.34366667 | AU17: =X17/$AA$1 -> 0.33335667 | AV17: =AL17/1 -> 18.327929 | AW17: =Z17/$AL17*100 -> 29.428775 | AX17: =AA17/$AL17*100 -> 16.469346 | AY17: =AB17/$AL17*100 -> 0.88281661 | AZ17: =AC17/$AL17*100 -> 25.413215 | BA17: =AD17/$AL17*100 -> 0.98702587 | BB17: =AE17/$AL17*100 -> 2.8834464 | BC17: =AF17/$AL17*100 -> 0.22806723 | BD17: =AG17/$AL17*100 -> 2.8448386 | ... BH17: =AK17/$AL17*100 -> 0
B18: =D18-D17 -> 1 | C18: =C17+B18 -> 15 | D18: 44755 | E18: 0.5 | F18: =AVERAGEA(F17,F19) -> 26.73 | G18: =AVERAGEA(G17,G19) -> 42.2975 | H18: =AVERAGEA(H17,H19) -> 4.765 | I18: =AVERAGEA(I17,I19) -> 27.3425 | J18: =AVERAGEA(J17,J19) -> 0.045 | K18: 4.74 | L18: 1.777 | M18: 0.079 | N18: 3.049 | O18: 0.087 | P18: 0.294 | Q18: 0 | R18: 0.314 | S18: 0.3798 | T18: 1.3870286 | U18: 1.0002857 | V18: 0 | W18: =SUM(K18:V18) -> 13.107114 | X18: =SUM(K18:R18) -> 10.34 | Y18: =C18 -> 15 | Z18: =K18*$E$2 -> 5.05758 | AA18: =L18*$G$2 -> 2.68327 | AB18: =M18*$H$2 -> 0.143622 | AC18: =N18*$J$2 -> 5.543082 | AD18: =O18*$K$2 -> 0.1768362 | AE18: =P18*$K$2 -> 0.5975844 | AF18: =Q18*$N$2 -> 0 | AG18: =R18*$N$2 -> 0.6908 | AH18: =S17*1.067 -> 0.090542571 | AI18: =T18*$B$2 -> 1.3149031 | AJ18: =U18*$D$2 -> 1.3903971 | AK18: =V18*$C$2 -> 0 | AL18: =SUM(Z18:AK18) -> 17.688617 | AM18: =(AL18/($AG$2))*100 -> 46.064108 | AN18: =712*40/1000 -> 28.48 | AO18: =848*20/1000 -> 16.96 | AP18: =AL18/AO18*100 -> 104.29609 | AQ18: =AO18/AN18 -> 0.59550562 | AR18: =($AG$2-AN18)/$AG$2*100 -> 25.833333 | AS18: =((W18)/$AC$1) -> 0.43690381 | AT18: =((X18)/$AC$1) -> 0.34466667 | AU18: =X18/$AA$1 -> 0.33432667 | AV18: =AL18/1 -> 17.688617 | AW18: =Z18/$AL18*100 -> 28.592286 | AX18: =AA18/$AL18*100 -> 15.169473 | AY18: =AB18/$AL18*100 -> 0.81194588 | AZ18: =AC18/$AL18*100 -> 31.337 | BA18: =AD18/$AL18*100 -> 0.99971748 | BB18: =AE18/$AL18*100 -> 3.3783556 | BC18: =AF18/$AL18*100 -> 0 | BD18: =AG18/$AL18*100 -> 3.9053363 | ... BH18: =AK18/$AL18*100 -> 0
B19: =D19-D18 -> 5 | C19: =C18+B19 -> 20 | D19: 44760 | E19: 0.5 | F19: =AVERAGEA(F14,F16) -> 28.46 | G19: =AVERAGEA(G14,G16) -> 49.235 | H19: =AVERAGEA(H14,H16) -> 4.67 | I19: =AVERAGEA(I14,I16) -> 19.955 | J19: =AVERAGEA(J14,J16) -> 0.04 | K19: 4.015 | L19: 1.022 | M19: 0.06 | N19: 2.51 | O19: 0.069 | P19: 0.341 | Q19: 0 | R19: 0.463 | S19: 0.91954286 | T19: 1.4096571 | U19: 0.73234286 | V19: 0 | W19: =SUM(K19:V19) -> 11.541543 | X19: =SUM(K19:R19) -> 8.48 | Y19: =C19 -> 20 | Z19: =K19*$E$2 -> 4.284005 | AA19: =L19*$G$2 -> 1.54322 | AB19: =M19*$H$2 -> 0.10908 | AC19: =N19*$J$2 -> 4.56318 | AD19: =O19*$K$2 -> 0.1402494 | AE19: =P19*$K$2 -> 0.6931166 | AF19: =Q19*$N$2 -> 0 | AG19: =R19*$N$2 -> 1.0186 | AH19: =U17*1.067 -> 0.91009003 | AI19: =T19*$B$2 -> 1.336355 | AJ19: =U19*$D$2 -> 1.0179566 | AK19: =V19*$C$2 -> 0 | AL19: =SUM(Z19:AK19) -> 15.615853 | AM19: =(AL19/($AG$2))*100 -> 40.666283 | AS19: =((W19)/$AC$1) -> 0.3847181 | AT19: =((X19)/$AC$1) -> 0.28266667 | AU19: =X19/$AA$1 -> 0.27418667 | AV19: =AL19/1 -> 15.615853 | AW19: =Z19/$AL19*100 -> 27.433693 | AX19: =AA19/$AL19*100 -> 9.8823935 | AY19: =AB19/$AL19*100 -> 0.69852094 | AZ19: =AC19/$AL19*100 -> 29.221459 | BA19: =AD19/$AL19*100 -> 0.89812195 | BB19: =AE19/$AL19*100 -> 4.4385447 | BC19: =AF19/$AL19*100 -> 0 | BD19: =AG19/$AL19*100 -> 6.5228587 | ... BH19: =AK19/$AL19*100 -> 0
B20: =D20-D19 -> 1 | C20: =C19+B20 -> 21 | D20: 44761 | E20: 0.5 | K20: 3.481 | L20: 0.952 | M20: 0.051 | N20: 2.751 | O20: 0.049 | P20: 0.248 | Q20: 0 | R20: 0.476 | S20: 0.36951429 | T20: 1.3988571 | U20: 1.0188 | V20: 0 | W20: =SUM(K20:V20) -> 10.795171 | X20: =SUM(K20:R20) -> 8.008 | Y20: =C20 -> 21 | Z20: =K20*$E$2 -> 3.714227 | AA20: =L20*$G$2 -> 1.43752 | AB20: =M20*$H$2 -> 0.092718 | AC20: =N20*$J$2 -> 5.001318 | AD20: =O20*$K$2 -> 0.0995974 | AE20: =P20*$K$2 -> 0.5040848 | AF20: =Q20*$N$2 -> 0 | AG20: =R20*$N$2 -> 1.0472 | AH20: =S20*1.067 -> 0.39427174 | AI20: =T20*$B$2 -> 1.3261166 | AJ20: =U20*$D$2 -> 1.416132 | AK20: =V20*$C$2 -> 0 | AL20: =SUM(Z20:AK20) -> 15.033186 | AM20: =(AL20/($AG$3))*100 -> 26.09928 | AS20: =((W20)/$AC$2) -> 0.2398927 | AT20: =((X20)/$AC$2) -> 0.17795556 | AU20: =X20/$AA$2 -> 0.17261689 | AV20: =AL20/1 -> 15.033186 | AW20: =Z20/$AL20*100 -> 24.706853 | AX20: =AA20/$AL20*100 -> 9.5623113 | AY20: =AB20/$AL20*100 -> 0.61675551 | AZ20: =AC20/$AL20*100 -> 33.268518 | BA20: =AD20/$AL20*100 -> 0.66251694 | BB20: =AE20/$AL20*100 -> 3.3531469 | BC20: =AF20/$AL20*100 -> 0 | BD20: =AG20/$AL20*100 -> 6.9659222 | ... BH20: =AK20/$AL20*100 -> 0
A21: OLR 45 g VS/Ld | B21: =D21-D20 -> 1 | C21: =C20+B21 -> 22 | D21: 44762 | E21: 0.5 | F21: 10.87 | G21: 30.19 | H21: 10,64 | I21: 48.25 | J21: 0.05 | K21: 3.54 | L21: 1.275 | M21: 0.081 | N21: 2.388 | O21: 0.069 | P21: 0.277 | Q21: 0 | R21: 0.571 | S21: 0.36951429 | T21: 1.3988571 | U21: 1.0188 | V21: 0 | W21: =SUM(K21:V21) -> 10.988171 | X21: =SUM(K21:R21) -> 8.201 | Y21: =C21 -> 22 | Z21: =K21*$E$2 -> 3.77718 | AA21: =L21*$G$2 -> 1.92525 | AB21: =M21*$H$2 -> 0.147258 | AC21: =N21*$J$2 -> 4.341384 | AD21: =O21*$K$2 -> 0.1402494 | AE21: =P21*$K$2 -> 0.5630302 | AF21: =Q21*$N$2 -> 0 | AG21: =R21*$N$2 -> 1.2562 | AH21: =S21*1.067 -> 0.39427174 | AI21: =T21*$B$2 -> 1.3261166 | AJ21: =U21*$D$2 -> 1.416132 | AK21: =V21*$C$2 -> 0 | AL21: =SUM(Z21:AK21) -> 15.287072 | AM21: =(AL21/($AG$3))*100 -> 26.540055 | AS21: =((W21)/$AC$2) -> 0.24418159 | AT21: =((X21)/$AC$2) -> 0.18224444 | AU21: =X21/$AA$2 -> 0.17677711 | AV21: =AL21/1 -> 15.287072 | AW21: =Z21/$AL21*100 -> 24.708329 | AX21: =AA21/$AL21*100 -> 12.593975 | AY21: =AB21/$AL21*100 -> 0.96328454 | AZ21: =AC21/$AL21*100 -> 28.399055 | BA21: =AD21/$AL21*100 -> 0.91743796 | BB21: =AE21/$AL21*100 -> 3.683048 | BC21: =AF21/$AL21*100 -> 0 | BD21: =AG21/$AL21*100 -> 8.217401 | ... BH21: =AK21/$AL21*100 -> 0
B22: =D22-D21 -> 1 | C22: =C21+B22 -> 23 | D22: 44763 | E22: 0.5 | F22: 26.08 | G22: 61.92 | H22: 2.19 | I22: 9.61 | J22: 0.2 | K22: 4.685 | L22: 1.397 | M22: 0.091 | N22: 2.263 | O22: 0.067 | P22: 0.312 | Q22: 0 | R22: 0.563 | S22: 0.96068571 | T22: 1.8288 | U22: 1.2967714 | V22: 0 | W22: =SUM(K22:V22) -> 13.464257 | X22: =SUM(K22:R22) -> 9.378 | Y22: =C22 -> 23 | Z22: =K22*$E$2 -> 4.998895 | AA22: =L22*$G$2 -> 2.10947 | AB22: =M22*$H$2 -> 0.165438 | AC22: =N22*$J$2 -> 4.114134 | AD22: =O22*$K$2 -> 0.1361842 | AE22: =P22*$K$2 -> 0.6341712 | AF22: =Q22*$N$2 -> 0 | AG22: =R22*$N$2 -> 1.2386 | AH22: =S22*1.067 -> 1.0250517 | AI22: =T22*$B$2 -> 1.7337024 | AJ22: =U22*$D$2 -> 1.8025123 | AK22: =V22*$C$2 -> 0 | AL22: =SUM(Z22:AK22) -> 17.958159 | AM22: =(AL22/($AG$3))*100 -> 31.177359 | AS22: =((W22)/$AC$2) -> 0.29920571 | AT22: =((X22)/$AC$2) -> 0.2084 | AU22: =X22/$AA$2 -> 0.202148 | AV22: =AL22/1 -> 17.958159 | AW22: =Z22/$AL22*100 -> 27.836345 | AX22: =AA22/$AL22*100 -> 11.746583 | AY22: =AB22/$AL22*100 -> 0.92124144 | AZ22: =AC22/$AL22*100 -> 22.909554 | BA22: =AD22/$AL22*100 -> 0.75834166 | BB22: =AE22/$AL22*100 -> 3.5313821 | BC22: =AF22/$AL22*100 -> 0 | BD22: =AG22/$AL22*100 -> 6.8971436 | ... BH22: =AK22/$AL22*100 -> 0
B23: =D23-D22 -> 1 | C23: =C22+B23 -> 24 | D23: 44764 | E23: 0.5 | F23: 25.87 | G23: 63.92 | H23: 0.07 | I23: 9,7 | J23: 0.44 | K23: 5.648 | L23: 1.416 | M23: 0.068 | N23: 1.792 | O23: 0.037 | P23: 0.346 | Q23: 0.048 | R23: 0.528 | S23: 1.1247429 | T23: 2.6187429 | U23: 1.4065714 | V23: 0 | W23: =SUM(K23:V23) -> 15.033057 | X23: =SUM(K23:R23) -> 9.883 | Y23: =C23 -> 24 | Z23: =K23*$E$2 -> 6.026416 | AA23: =L23*$G$2 -> 2.13816 | AB23: =M23*$H$2 -> 0.123624 | AC23: =N23*$J$2 -> 3.257856 | AD23: =O23*$K$2 -> 0.0752062 | AE23: =P23*$K$2 -> 0.7032796 | AF23: =Q23*$N$2 -> 0.1056 | AG23: =R23*$N$2 -> 1.1616 | AH23: =S23*1.067 -> 1.2001006 | AI23: =T23*$B$2 -> 2.4825682 | AJ23: =U23*$D$2 -> 1.9551343 | AK23: =V23*$C$2 -> 0 | AL23: =SUM(Z23:AK23) -> 19.229545 | AM23: =(AL23/($AG$3))*100 -> 33.384627 | AN23: =1062*40/1000 -> 42.48 | AO23: =625*40/1000 -> 25 | AP23: =AL23/AO23*100 -> 76.91818 | AQ23: =AO23/AN23 -> 0.58851224 | AR23: =($AG$3-AN23)/$AG$3*100 -> 26.25 | AS23: =((W23)/$AC$2) -> 0.33406794 | AT23: =((X23)/$AC$2) -> 0.21962222 | AU23: =X23/$AA$2 -> 0.21303356 | AV23: =AL23/1 -> 19.229545 | AW23: =Z23/$AL23*100 -> 31.339358 | AX23: =AA23/$AL23*100 -> 11.11914 | AY23: =AB23/$AL23*100 -> 0.64288573 | AZ23: =AC23/$AL23*100 -> 16.94193 | BA23: =AD23/$AL23*100 -> 0.39109714 | BB23: =AE23/$AL23*100 -> 3.6572868 | BC23: =AF23/$AL23*100 -> 0.54915496 | BD23: =AG23/$AL23*100 -> 6.0407046 | ... BH23: =AK23/$AL23*100 -> 0
B24: =D24-D23 -> 3 | C24: =C23+B24 -> 27 | D24: 44767 | E24: 0.5 | F24: 26.25 | G24: 66.62 | I24: 6.38 | J24: 0.76 | K24: 6.492 | L24: 1.765 | M24: 0.089 | N24: 1.737 | O24: 0.053 | P24: 0.609 | Q24: 0.035 | R24: 0.699 | S24: 0 | T24: 2.5691143 | U24: 1.1900571 | V24: 0 | W24: =SUM(K24:V24) -> 15.238171 | X24: =SUM(K24:R24) -> 11.479 | Y24: =C24 -> 27 | Z24: =K24*$E$2 -> 6.926964 | AA24: =L24*$G$2 -> 2.66515 | AB24: =M24*$H$2 -> 0.161802 | AC24: =N24*$J$2 -> 3.157866 | AD24: =O24*$K$2 -> 0.1077278 | AE24: =P24*$K$2 -> 1.2378534 | AF24: =Q24*$N$2 -> 0.077 | AG24: =R24*$N$2 -> 1.5378 | AH24: =S24*1.067 -> 0 | AI24: =T24*$B$2 -> 2.4355203 | AJ24: =U24*$D$2 -> 1.6541794 | AK24: =V24*$C$2 -> 0 | AL24: =SUM(Z24:AK24) -> 19.961863 | AM24: =(AL24/($AG$3))*100 -> 34.656012 | AN24: =1068*40/1000 -> 42.72 | AO24: =588*40/1000 -> 23.52 | AP24: =AL24/AO24*100 -> 84.871866 | AQ24: =AO24/AN24 -> 0.5505618 | AR24: =($AG$3-AN24)/$AG$3*100 -> 25.833333 | AS24: =((W24)/$AC$2) -> 0.33862603 | AT24: =((X24)/$AC$2) -> 0.25508889 | AU24: =X24/$AA$2 -> 0.24743622 | AV24: =AL24/1 -> 19.961863 | AW24: =Z24/$AL24*100 -> 34.70099 | AX24: =AA24/$AL24*100 -> 13.351209 | AY24: =AB24/$AL24*100 -> 0.81055561 | AZ24: =AC24/$AL24*100 -> 15.819495 | BA24: =AD24/$AL24*100 -> 0.53966807 | BB24: =AE24/$AL24*100 -> 6.2010916 | BC24: =AF24/$AL24*100 -> 0.38573554 | BD24: =AG24/$AL24*100 -> 7.7036898 | ... BH24: =AK24/$AL24*100 -> 0
B25: =D25-D24 -> 1 | C25: =C24+B25 -> 28 | D25: 44768 | E25: 0.5 | K25: 6.445 | L25: 1.749 | M25: 0.136 | N25: 1.915 | O25: 0.054 | P25: 0.566 | Q25: 0.029 | R25: 0.662 | S25: 0 | T25: 2.3433429 | U25: 1.5081429 | V25: 0 | W25: =SUM(K25:V25) -> 15.407486 | X25: =SUM(K25:R25) -> 11.556 | Y25: =C25 -> 28 | Z25: =K25*$E$2 -> 6.876815 | AA25: =L25*$G$2 -> 2.64099 | AB25: =M25*$H$2 -> 0.247248 | AC25: =N25*$J$2 -> 3.48147 | AD25: =O25*$K$2 -> 0.1097604 | AE25: =P25*$K$2 -> 1.1504516 | AF25: =Q25*$N$2 -> 0.0638 | AG25: =R25*$N$2 -> 1.4564 | AH25: =S25*1.067 -> 0 | AI25: =T25*$B$2 -> 2.221489 | AJ25: =U25*$D$2 -> 2.0963186 | AK25: =V25*$C$2 -> 0 | AL25: =SUM(Z25:AK25) -> 20.344743 | AM25: =(AL25/($AG$3))*100 -> 35.320734 | AS25: =((W25)/$AC$2) -> 0.34238857 | AT25: =((X25)/$AC$2) -> 0.2568 | AU25: =X25/$AA$2 -> 0.249096 | AV25: =AL25/1 -> 20.344743 | AW25: =Z25/$AL25*100 -> 33.801435 | AX25: =AA25/$AL25*100 -> 12.981192 | AY25: =AB25/$AL25*100 -> 1.2152919 | AZ25: =AC25/$AL25*100 -> 17.112382 | BA25: =AD25/$AL25*100 -> 0.53950252 | BB25: =AE25/$AL25*100 -> 5.6547857 | BC25: =AF25/$AL25*100 -> 0.31359453 | BD25: =AG25/$AL25*100 -> 7.1586062 | ... BH25: =AK25/$AL25*100 -> 0
B26: =D26-D25 -> 1 | C26: =C25+B26 -> 29 | D26: 44769 | E26: 0.5 | F26: 34.79 | G26: 55.14 | H26: 0.13 | I26: 8.45 | J26: 1.5 | K26: 7.67 | L26: 2.523 | M26: 0.137 | N26: 2.519 | O26: 0.155 | P26: 1.025 | Q26: 0.034 | R26: 1.061 | S26: 0.038314286 | T26: 1.818 | U26: 1.5202286 | V26: 0 | W26: =SUM(K26:V26) -> 18.500543 | X26: =SUM(K26:R26) -> 15.124 | Y26: =C26 -> 29 | Z26: =K26*$E$2 -> 8.18389 | AA26: =L26*$G$2 -> 3.80973 | AB26: =M26*$H$2 -> 0.249066 | AC26: =N26*$J$2 -> 4.579542 | AD26: =O26*$K$2 -> 0.315053 | AE26: =P26*$K$2 -> 2.083415 | AF26: =Q26*$N$2 -> 0.0748 | AG26: =R26*$N$2 -> 2.3342 | AH26: =S26*1.067 -> 0.040881343 | AI26: =T26*$B$2 -> 1.723464 | AJ26: =U26*$D$2 -> 2.1131177 | AK26: =V26*$C$2 -> 0 | AL26: =SUM(Z26:AK26) -> 25.507159 | AM26: =(AL26/($AG$3))*100 -> 44.283262 | AN26: =1459*40/1000 -> 58.36 | AO26: =741*40/1000 -> 29.64 | AP26: =AL26/AO26*100 -> 86.056542 | AQ26: =AO26/AN26 -> 0.50788211 | AR26: =($AG$3-AN26)/$AG$3*100 -> -1.3194444 | AS26: =((W26)/$AC$2) -> 0.41112317 | AT26: =((X26)/$AC$2) -> 0.33608889 | AU26: =X26/$AA$2 -> 0.32600622 | AV26: =AL26/1 -> 25.507159 | AW26: =Z26/$AL26*100 -> 32.084679 | AX26: =AA26/$AL26*100 -> 14.935924 | AY26: =AB26/$AL26*100 -> 0.97645527 | AZ26: =AC26/$AL26*100 -> 17.953948 | BA26: =AD26/$AL26*100 -> 1.2351552 | BB26: =AE26/$AL26*100 -> 8.1679618 | BC26: =AF26/$AL26*100 -> 0.293251 | BD26: =AG26/$AL26*100 -> 9.1511563 | ... BH26: =AK26/$AL26*100 -> 0
B27: =D27-D26 -> 1 | C27: =C26+B27 -> 30 | D27: 44770 | E27: 0.5 | F27: 32.9 | G27: 58.9 | I27: 6.76 | J27: 1.42 | K27: 7.082 | L27: 2.058 | M27: 0.178 | N27: 2.778 | O27: 0.09 | P27: 0.6354 | Q27: 0 | R27: 0.741 | S27: 0.4734 | T27: 2.7262286 | U27: 2.0232 | V27: 0 | W27: =SUM(K27:V27) -> 18.785229 | X27: =SUM(K27:R27) -> 13.5624 | Y27: =C27 -> 30 | Z27: =K27*$E$2 -> 7.556494 | AA27: =L27*$G$2 -> 3.10758 | AB27: =M27*$H$2 -> 0.323604 | AC27: =N27*$J$2 -> 5.050404 | AD27: =O27*$K$2 -> 0.182934 | AE27: =P27*$K$2 -> 1.291514 | AF27: =Q27*$N$2 -> 0 | AG27: =R27*$N$2 -> 1.6302 | AH27: =S27*1.067 -> 0.5051178 | AI27: =T27*$B$2 -> 2.5844647 | AJ27: =U27*$D$2 -> 2.812248 | AK27: =V27*$C$2 -> 0 | AL27: =SUM(Z27:AK27) -> 25.044561 | AM27: =(AL27/($AG$3))*100 -> 43.48014 | AS27: =((W27)/$AC$2) -> 0.41744952 | AT27: =((X27)/$AC$2) -> 0.30138667 | AU27: =X27/$AA$2 -> 0.29234507 | AV27: =AL27/1 -> 25.044561 | AW27: =Z27/$AL27*100 -> 30.172196 | AX27: =AA27/$AL27*100 -> 12.408203 | AY27: =AB27/$AL27*100 -> 1.2921129 | AZ27: =AC27/$AL27*100 -> 20.165672 | BA27: =AD27/$AL27*100 -> 0.73043406 | BB27: =AE27/$AL27*100 -> 5.1568645 | BC27: =AF27/$AL27*100 -> 0 | BD27: =AG27/$AL27*100 -> 6.5091979 | ... BH27: =AK27/$AL27*100 -> 0
B28: =D28-D27 -> 1 | C28: =C27+B28 -> 31 | D28: 44771 | E28: 0.5 | F28: 26.56 | G28: 55.85 | H28: 2.86 | I28: 13.43 | J28: 1.3 | K28: 6.341 | L28: 1.45 | M28: 0.087 | N28: 2.247 | O28: 0.064 | P28: 0.375 | Q28: 0 | R28: 0.541 | S28: 1.1232 | T28: 2.9399143 | U28: 1.6763143 | V28: 0 | W28: =SUM(K28:V28) -> 16.844429 | X28: =SUM(K28:R28) -> 11.105 | Y28: =C28 -> 31 | Z28: =K28*$E$2 -> 6.765847 | AA28: =L28*$G$2 -> 2.1895 | AB28: =M28*$H$2 -> 0.158166 | AC28: =N28*$J$2 -> 4.085046 | AD28: =O28*$K$2 -> 0.1300864 | AE28: =P28*$K$2 -> 0.762225 | AF28: =Q28*$N$2 -> 0 | AG28: =R28*$N$2 -> 1.1902 | AH28: =S28*1.067 -> 1.1984544 | AI28: =T28*$B$2 -> 2.7870387 | AJ28: =U28*$D$2 -> 2.3300769 | AK28: =V28*$C$2 -> 0 | AL28: =SUM(Z28:AK28) -> 21.59664 | AM28: =(AL28/($AG$3))*100 -> 37.494167 | AN28: =1163*40/1000 -> 46.52 | AO28: =650*40/1000 -> 26 | AP28: =AL28/AO28*100 -> 83.064002 | AQ28: =AO28/AN28 -> 0.5588994 | AR28: =($AG$3-AN28)/$AG$3*100 -> 19.236111 | AS28: =((W28)/$AC$2) -> 0.37432063 | AT28: =((X28)/$AC$2) -> 0.24677778 | AU28: =X28/$AA$2 -> 0.23937444 | AV28: =AL28/1 -> 21.59664 | AW28: =Z28/$AL28*100 -> 31.328238 | AX28: =AA28/$AL28*100 -> 10.138151 | AY28: =AB28/$AL28*100 -> 0.73236391 | AZ28: =AC28/$AL28*100 -> 18.915192 | BA28: =AD28/$AL28*100 -> 0.60234554 | BB28: =AE28/$AL28*100 -> 3.5293684 | BC28: =AF28/$AL28*100 -> 0 | BD28: =AG28/$AL28*100 -> 5.5110424 | ... BH28: =AK28/$AL28*100 -> 0
B29: =D29-D28 -> 3 | C29: =C28+B29 -> 34 | D29: 44774 | E29: 0.5 | K29: 7.71 | L29: 1.393 | M29: 0.03 | N29: 1.315 | O29: 0.011 | P29: 0.192 | Q29: 0 | R29: 0.273 | S29: 4.0219714 | T29: 3.1062857 | U29: 0.67165714 | V29: 1.5588 | W29: =SUM(K29:V29) -> 20.282714 | X29: =SUM(K29:R29) -> 10.924 | Y29: =C29 -> 34 | Z29: =K29*$E$2 -> 8.22657 | AA29: =L29*$G$2 -> 2.10343 | AB29: =M29*$H$2 -> 0.05454 | AC29: =N29*$J$2 -> 2.39067 | AD29: =O29*$K$2 -> 0.0223586 | AE29: =P29*$K$2 -> 0.3902592 | AF29: =Q29*$N$2 -> 0 | AG29: =R29*$N$2 -> 0.6006 | AH29: =S29*1.067 -> 4.2914435 | AI29: =T29*$B$2 -> 2.9447589 | AJ29: =U29*$D$2 -> 0.93360343 | AK29: =V29*$C$2 -> 3.248851 | AL29: =SUM(Z29:AK29) -> 25.207085 | AM29: =(AL29/($AG$3))*100 -> 43.7623 | AN29: =1378*40/1000 -> 55.12 | AO29: =696*40/1000 -> 27.84 | AP29: =AL29/AO29*100 -> 90.542689 | AQ29: =AO29/AN29 -> 0.50507983 | AR29: =($AG$3-AN29)/$AG$3*100 -> 4.3055556 | AS29: =((W29)/$AC$2) -> 0.45072698 | AT29: =((X29)/$AC$2) -> 0.24275556 | AU29: =X29/$AA$2 -> 0.23547289 | AV29: =AL29/1 -> 25.207085 | AW29: =Z29/$AL29*100 -> 32.635944 | AX29: =AA29/$AL29*100 -> 8.3445985 | AY29: =AB29/$AL29*100 -> 0.21636774 | AZ29: =AC29/$AL29*100 -> 9.4841194 | BA29: =AD29/$AL29*100 -> 0.088699667 | BB29: =AE29/$AL29*100 -> 1.5482124 | BC29: =AF29/$AL29*100 -> 0 | BD29: =AG29/$AL29*100 -> 2.3826635 | ... BH29: =AK29/$AL29*100 -> 12.888642
B30: =D30-D29 -> 1 | C30: =C29+B30 -> 35 | D30: 44775 | E30: 0.5 | F30: 17.46 | G30: 54.83 | H30: 5.14 | I30: 21.66 | J30: 0.91 | K30: 7.466 | L30: 1.591 | M30: 0.07 | N30: 1.243 | O30: 0.014 | P30: 0.172 | Q30: 0 | R30: 0.208 | S30: 3.6635143 | T30: 2.5518857 | U30: 0.72488571 | V30: 1.7529429 | W30: =SUM(K30:V30) -> 19.457229 | X30: =SUM(K30:R30) -> 10.764 | Y30: =C30 -> 35 | Z30: =K30*$E$2 -> 7.966222 | AA30: =L30*$G$2 -> 2.40241 | AB30: =M30*$H$2 -> 0.12726 | AC30: =N30*$J$2 -> 2.259774 | AD30: =O30*$K$2 -> 0.0284564 | AE30: =P30*$K$2 -> 0.3496072 | AF30: =Q30*$N$2 -> 0 | AG30: =R30*$N$2 -> 0.4576 | AH30: =S30*1.067 -> 3.9089697 | AI30: =T30*$B$2 -> 2.4191877 | AJ30: =U30*$D$2 -> 1.0075911 | AK30: =V30*$C$2 -> 3.6534835 | AL30: =SUM(Z30:AK30) -> 24.580562 | AM30: =(AL30/($AG$3))*100 -> 42.674586 | AS30: =((W30)/$AC$2) -> 0.43238286 | AT30: =((X30)/$AC$2) -> 0.2392 | AU30: =X30/$AA$2 -> 0.232024 | AV30: =AL30/1 -> 24.580562 | AW30: =Z30/$AL30*100 -> 32.408625 | AX30: =AA30/$AL30*100 -> 9.7736172 | AY30: =AB30/$AL30*100 -> 0.51772617 | AZ30: =AC30/$AL30*100 -> 9.1933375 | BA30: =AD30/$AL30*100 -> 0.1157679 | BB30: =AE30/$AL30*100 -> 1.4222913 | BC30: =AF30/$AL30*100 -> 0 | BD30: =AG30/$AL30*100 -> 1.8616336 | ... BH30: =AK30/$AL30*100 -> 14.863304
B31: =D31-D30 -> 1 | C31: =C30+B31 -> 36 | D31: 44776 | E31: 0.5 | F31: 25.87 | G31: 59.29 | H31: 2.76 | I31: 10.89 | J31: 1.18 | K31: 6.231 | L31: 2.213 | M31: 0.053 | N31: 1.345 | O31: 0.025 | P31: 0.235 | Q31: 0 | R31: 0.184 | S31: 1.9540286 | T31: 2.4876 | U31: 0.97662857 | V31: 1.7467714 | W31: =SUM(K31:V31) -> 17.451029 | X31: =SUM(K31:R31) -> 10.286 | Y31: =C31 -> 36 | Z31: =K31*$E$2 -> 6.648477 | AA31: =L31*$G$2 -> 3.34163 | AB31: =M31*$H$2 -> 0.096354 | AC31: =N31*$J$2 -> 2.44521 | AD31: =O31*$K$2 -> 0.050815 | AE31: =P31*$K$2 -> 0.477661 | AF31: =Q31*$N$2 -> 0 | AG31: =R31*$N$2 -> 0.4048 | AH31: =S31*1.067 -> 2.0849485 | AI31: =T31*$B$2 -> 2.3582448 | AJ31: =U31*$D$2 -> 1.3575137 | AK31: =V31*$C$2 -> 3.640621 | AL31: =SUM(Z31:AK31) -> 22.906275 | AM31: =(AL31/($AG$3))*100 -> 39.767839 | AN31: =1093*50/1000 -> 54.65 | AO31: =666*40/1000 -> 26.64 | AP31: =AL31/AO31*100 -> 85.984516 | AQ31: =AO31/AN31 -> 0.48746569 | AR31: =($AG$3-AN31)/$AG$3*100 -> 5.1215278 | AS31: =((W31)/$AC$2) -> 0.38780063 | AT31: =((X31)/$AC$2) -> 0.22857778 | AU31: =X31/$AA$2 -> 0.22172044 | AV31: =AL31/1 -> 22.906275 | AW31: =Z31/$AL31*100 -> 29.024697 | AX31: =AA31/$AL31*100 -> 14.588273 | AY31: =AB31/$AL31*100 -> 0.42064456 | AZ31: =AC31/$AL31*100 -> 10.674848 | BA31: =AD31/$AL31*100 -> 0.22183878 | BB31: =AE31/$AL31*100 -> 2.0852845 | BC31: =AF31/$AL31*100 -> 0 | BD31: =AG31/$AL31*100 -> 1.7672013 | ... BH31: =AK31/$AL31*100 -> 15.893553
B32: =D32-D31 -> 1 | C32: =C31+B32 -> 37 | D32: 44777 | E32: 0.5 | F32: 28.84 | G32: 60.58 | H32: 0.29 | I32: 8.41 | J32: 1.88 | K32: 5.751 | L32: 2.596 | M32: 0.098 | N32: 1.321 | O32: 0.037 | P32: 0.261 | Q32: 0 | R32: 0.178 | S32: 0.73954286 | T32: 2.6187429 | U32: 0.97997143 | V32: 1.6362 | W32: =SUM(K32:V32) -> 16.216457 | X32: =SUM(K32:R32) -> 10.242 | Y32: =C32 -> 37 | Z32: =K32*$E$2 -> 6.136317 | AA32: =L32*$G$2 -> 3.91996 | AB32: =M32*$H$2 -> 0.178164 | AC32: =N32*$J$2 -> 2.401578 | AD32: =O32*$K$2 -> 0.0752062 | AE32: =P32*$K$2 -> 0.5305086 | AF32: =Q32*$N$2 -> 0 | AG32: =R32*$N$2 -> 0.3916 | AH32: =S32*1.067 -> 0.78909223 | AI32: =T32*$B$2 -> 2.4825682 | AJ32: =U32*$D$2 -> 1.3621603 | AK32: =V32*$C$2 -> 3.410168 | AL32: =SUM(Z32:AK32) -> 21.677323 | AM32: =(AL32/($AG$3))*100 -> 37.634241 | AS32: =((W32)/$AC$2) -> 0.36036571 | AT32: =((X32)/$AC$2) -> 0.2276 | AU32: =X32/$AA$2 -> 0.220772 | AV32: =AL32/1 -> 21.677323 | AW32: =Z32/$AL32*100 -> 28.307541 | AX32: =AA32/$AL32*100 -> 18.08323 | AY32: =AB32/$AL32*100 -> 0.82189117 | AZ32: =AC32/$AL32*100 -> 11.078757 | BA32: =AD32/$AL32*100 -> 0.34693491 | BB32: =AE32/$AL32*100 -> 2.4472976 | BC32: =AF32/$AL32*100 -> 0 | BD32: =AG32/$AL32*100 -> 1.8064962 | ... BH32: =AK32/$AL32*100 -> 15.7315
B33: =D33-D32 -> 1 | C33: =C32+B33 -> 38 | D33: 44778 | E33: 0.5 | F33: 25.9 | G33: 64.31 | H33: 6.93 | I33: 2.85 | J33: 2.85 | K33: 6.98 | L33: 3.122 | M33: 0.136 | N33: 1.663 | O33: 0.055 | P33: 0.369 | Q33: 0 | R33: 0.249 | S33: 0.5832 | T33: 3.6208286 | U33: 1.0836 | V33: 1.2800571 | W33: =SUM(K33:V33) -> 19.141686 | X33: =SUM(K33:R33) -> 12.574 | Y33: =C33 -> 38 | Z33: =K33*$E$2 -> 7.44766 | AA33: =L33*$G$2 -> 4.71422 | AB33: =M33*$H$2 -> 0.247248 | AC33: =N33*$J$2 -> 3.023334 | AD33: =O33*$K$2 -> 0.111793 | AE33: =P33*$K$2 -> 0.7500294 | AF33: =Q33*$N$2 -> 0 | AG33: =R33*$N$2 -> 0.5478 | AH33: =S33*1.067 -> 0.6222744 | AI33: =T33*$B$2 -> 3.4325455 | AJ33: =U33*$D$2 -> 1.506204 | AK33: =V33*$C$2 -> 2.6678951 | AL33: =SUM(Z33:AK33) -> 25.071003 | AM33: =(AL33/($AG$3))*100 -> 43.526048 | AN33: =1087*50/1000 -> 54.35 | AO33: =644*40/1000 -> 25.76 | AP33: =AL33/AO33*100 -> 97.325324 | AQ33: =AO33/AN33 -> 0.47396504 | AR33: =($AG$3-AN33)/$AG$3*100 -> 5.6423611 | AS33: =((W33)/$AC$2) -> 0.42537079 | AT33: =((X33)/$AC$2) -> 0.27942222 | AU33: =X33/$AA$2 -> 0.27103956 | AV33: =AL33/1 -> 25.071003 | AW33: =Z33/$AL33*100 -> 29.70627 | AX33: =AA33/$AL33*100 -> 18.803476 | AY33: =AB33/$AL33*100 -> 0.98619108 | AZ33: =AC33/$AL33*100 -> 12.059087 | BA33: =AD33/$AL33*100 -> 0.44590557 | BB33: =AE33/$AL33*100 -> 2.991621 | BC33: =AF33/$AL33*100 -> 0 | BD33: =AG33/$AL33*100 -> 2.1849943 | ... BH33: =AK33/$AL33*100 -> 10.641357
B34: =D34-D33 -> 3 | C34: =C33+B34 -> 41 | D34: 44781 | E34: 0.5 | F34: 15.41 | G34: 73.06 | I34: 7.63 | J34: 3.89 | K34: 7.122 | L34: 2.398 | M34: 0.094 | N34: 1.591 | O34: 0.053 | P34: 0.347 | Q34: 0 | R34: 0.274 | S34: =AVERAGEA(S33,S36) -> 0.56507143 | T34: =AVERAGEA(T33,T36) -> 4.4930571 | U34: =AVERAGEA(U33,U36) -> 1.116 | V34: =AVERAGEA(V33,V36) -> 1.5158571 | W34: =SUM(K34:V34) -> 19.568986 | X34: =SUM(K34:R34) -> 11.879 | Y34: =C34 -> 41 | Z34: =K34*$E$2 -> 7.599174 | AA34: =L34*$G$2 -> 3.62098 | AB34: =M34*$H$2 -> 0.170892 | AC34: =N34*$J$2 -> 2.892438 | AD34: =O34*$K$2 -> 0.1077278 | AE34: =P34*$K$2 -> 0.7053122 | AF34: =Q34*$N$2 -> 0 | AG34: =R34*$N$2 -> 0.6028 | AH34: =S34*1.067 -> 0.60293121 | AI34: =T34*$B$2 -> 4.2594182 | AJ34: =U34*$D$2 -> 1.55124 | AK34: =V34*$C$2 -> 3.1593495 | AL34: =SUM(Z34:AK34) -> 25.272263 | AM34: =(AL34/($AG$3))*100 -> 43.875456 | AN34: =862*50/1000 -> 43.1 | AO34: =640*40/1000 -> 25.6 | AP34: =AL34/AO34*100 -> 98.719777 | AQ34: =AO34/AN34 -> 0.59396752 | AR34: =($AG$3-AN34)/$AG$3*100 -> 25.173611 | AS34: =((W34)/$AC$2) -> 0.43486635 | AT34: =((X34)/$AC$2) -> 0.26397778 | AU34: =X34/$AA$2 -> 0.25605844 | AV34: =AL34/1 -> 25.272263 | AW34: =Z34/$AL34*100 -> 30.069227 | AX34: =AA34/$AL34*100 -> 14.327882 | AY34: =AB34/$AL34*100 -> 0.67620379 | AZ34: =AC34/$AL34*100 -> 11.445109 | BA34: =AD34/$AL34*100 -> 0.42626891 | BB34: =AE34/$AL34*100 -> 2.790855 | BC34: =AF34/$AL34*100 -> 0 | BD34: =AG34/$AL34*100 -> 2.3852237 | ... BH34: =AK34/$AL34*100 -> 12.501253
A35: OLR 60 g VS/Ld | B35: =D35-D34 -> 1 | C35: =C34+B35 -> 42 | D35: 44782 | E35: 0.5 | F35: 10.53 | G35: 54.87 | H35: 2.2 | I35: 29.75 | J35: 2.65 | Y35: =C35 -> 42
B36: =D36-D35 -> 1 | C36: =C35+B36 -> 43 | D36: 44783 | E36: 0.5 | F36: 6.62 | G36: 59.01 | H36: 2.66 | I36: 29.41 | J36: 2.31 | K36: 5.868 | L36: 1.319 | M36: 0.089 | N36: 1.024 | O36: 0.022 | P36: 0.182 | Q36: 0 | R36: 0.186 | S36: 0.54694286 | T36: 5.3652857 | U36: 1.1484 | V36: 1.7516571 | W36: =SUM(K36:V36) -> 17.502286 | X36: =SUM(K36:R36) -> 8.69 | Y36: =C36 -> 43 | Z36: =K36*$E$2 -> 6.261156 | AA36: =L36*$G$2 -> 1.99169 | AB36: =M36*$H$2 -> 0.161802 | AC36: =N36*$J$2 -> 1.861632 | AD36: =O36*$K$2 -> 0.0447172 | AE36: =P36*$K$2 -> 0.3699332 | AF36: =Q36*$N$2 -> 0 | AG36: =R36*$N$2 -> 0.4092 | AH36: =S36*1.067 -> 0.58358803 | AI36: =T36*$B$2 -> 5.0862909 | AJ36: =U36*$D$2 -> 1.596276 | AK36: =V36*$C$2 -> 3.6508038 | AL36: =SUM(Z36:AK36) -> 22.017089 | AM36: =(AL36/($AG$3))*100 -> 38.224113 | AS36: =((W36)/$AC$2) -> 0.38893968 | AT36: =((X36)/$AC$2) -> 0.19311111 | AU36: =X36/$AA$2 -> 0.18731778 | AV36: =AL36/0.75 -> 29.356119 | AW36: =Z36/$AL36*100 -> 28.43771 | AX36: =AA36/$AL36*100 -> 9.0461096 | AY36: =AB36/$AL36*100 -> 0.73489279 | AZ36: =AC36/$AL36*100 -> 8.4553957 | BA36: =AD36/$AL36*100 -> 0.20310223 | BB36: =AE36/$AL36*100 -> 1.6802094 | BC36: =AF36/$AL36*100 -> 0 | BD36: =AG36/$AL36*100 -> 1.8585563 | ... BH36: =AK36/$AL36*100 -> 16.581683
B37: =D37-D36 -> 1 | C37: =C36+B37 -> 44 | D37: 44784 | E37: 0.5 | F37: 5.77 | G37: 67.54 | H37: 0 | I37: 24.01 | J37: 2.68 | K37: 6.899 | L37: 1.384 | M37: 0.037 | N37: 1.003 | O37: 0.017 | P37: 0.169 | Q37: 0.017 | R37: 0.178 | S37: 1.7046 | T37: 6.6736286 | U37: 1.2731143 | V37: 1.5860571 | W37: =SUM(K37:V37) -> 20.9414 | X37: =SUM(K37:R37) -> 9.704 | Y37: =C37 -> 44 | Z37: =K37*$E$2 -> 7.361233 | AA37: =L37*$G$2 -> 2.08984 | AB37: =M37*$H$2 -> 0.067266 | AC37: =N37*$J$2 -> 1.823454 | AD37: =O37*$K$2 -> 0.0345542 | AE37: =P37*$K$2 -> 0.3435094 | AF37: =Q37*$N$2 -> 0.0374 | AG37: =R37*$N$2 -> 0.3916 | AH37: =S37*1.067 -> 1.8188082 | AI37: =T37*$B$2 -> 6.3265999 | AJ37: =U37*$D$2 -> 1.7696289 | AK37: =V37*$C$2 -> 3.3056603 | AL37: =SUM(Z37:AK37) -> 25.369554 | AM37: =(AL37/($AG$3))*100 -> 44.044364 | AN37: =881*50/1000 -> 44.05 | AO37: =618*40/1000 -> 24.72 | AP37: =AL37/AO37*100 -> 102.62764 | AQ37: =AO37/AN37 -> 0.56118048 | AR37: =($AG$3-AN37)/$AG$3*100 -> 23.524306 | AS37: =((W37)/$AC$2) -> 0.46536444 | AT37: =((X37)/$AC$2) -> 0.21564444 | AU37: =X37/$AA$2 -> 0.20917511 | AV37: =AL37/0.75 -> 33.826072 | AW37: =Z37/$AL37*100 -> 29.016013 | AX37: =AA37/$AL37*100 -> 8.2375907 | AY37: =AB37/$AL37*100 -> 0.26514459 | AZ37: =AC37/$AL37*100 -> 7.1875683 | BA37: =AD37/$AL37*100 -> 0.13620342 | BB37: =AE37/$AL37*100 -> 1.3540222 | BC37: =AF37/$AL37*100 -> 0.1474208 | BD37: =AG37/$AL37*100 -> 1.5435825 | ... BH37: =AK37/$AL37*100 -> 13.030029
B38: =D38-D37 -> 1 | C38: =C37+B38 -> 45 | D38: 44785 | E38: 0.5 | F38: 4.76 | G38: 80.46 | H38: 0 | I38: 12.78 | J38: 2 | K38: 7.193 | L38: 1.505 | M38: 0.032 | N38: 1.089 | O38: 0.019 | P38: 0.175 | Q38: 0.018 | R38: 0.183 | S38: 2.0800286 | T38: 7.2252 | U38: 1.5832286 | V38: 1.9787143 | W38: =SUM(K38:V38) -> 23.081171 | X38: =SUM(K38:R38) -> 10.214 | Y38: =C38 -> 45 | Z38: =K38*$E$2 -> 7.674931 | AA38: =L38*$G$2 -> 2.27255 | AB38: =M38*$H$2 -> 0.058176 | AC38: =N38*$J$2 -> 1.979802 | AD38: =O38*$K$2 -> 0.0386194 | AE38: =P38*$K$2 -> 0.355705 | AF38: =Q38*$N$2 -> 0.0396 | AG38: =R38*$N$2 -> 0.4026 | AH38: =S38*1.067 -> 2.2193905 | AI38: =T38*$B$2 -> 6.8494896 | AJ38: =U38*$D$2 -> 2.2006877 | AK38: =V38*$C$2 -> 4.1240363 | AL38: =SUM(Z38:AK38) -> 28.215588 | AM38: =(AL38/($AG$3))*100 -> 48.985395 | AS38: =((W38)/$AC$2) -> 0.51291492 | AT38: =((X38)/$AC$2) -> 0.22697778 | AU38: =X38/$AA$2 -> 0.22016844 | AV38: =AL38/0.75 -> 37.620783 | AW38: =Z38/$AL38*100 -> 27.201032 | AX38: =AA38/$AL38*100 -> 8.054236 | AY38: =AB38/$AL38*100 -> 0.2061839 | AZ38: =AC38/$AL38*100 -> 7.016696 | BA38: =AD38/$AL38*100 -> 0.13687257 | BB38: =AE38/$AL38*100 -> 1.2606684 | BC38: =AF38/$AL38*100 -> 0.14034795 | BD38: =AG38/$AL38*100 -> 1.4268709 | ... BH38: =AK38/$AL38*100 -> 14.616163
B39: =D39-D38 -> 4 | C39: =C38+B39 -> 49 | D39: 44789 | E39: 0.5 | K39: 5.447 | L39: 1.969 | M39: 0.042 | N39: 1.22 | O39: 0.026 | P39: 0.22 | Q39: 0.017 | R39: 0.246 | S39: 0.117 | T39: 4.6640571 | U39: 1.8100286 | V39: 2.1461143 | W39: =SUM(K39:V39) -> 17.9242 | X39: =SUM(K39:R39) -> 9.187 | Y39: =C39 -> 49 | Z39: =K39*$E$2 -> 5.811949 | AA39: =L39*$G$2 -> 2.97319 | AB39: =M39*$H$2 -> 0.076356 | AC39: =N39*$J$2 -> 2.21796 | AD39: =O39*$K$2 -> 0.0528476 | AE39: =P39*$K$2 -> 0.447172 | AF39: =Q39*$N$2 -> 0.0374 | AG39: =R39*$N$2 -> 0.5412 | AH39: =S39*1.067 -> 0.124839 | AI39: =T39*$B$2 -> 4.4215262 | AJ39: =U39*$D$2 -> 2.5159397 | AK39: =V39*$C$2 -> 4.4729314 | AL39: =SUM(Z39:AK39) -> 23.693311 | AM39: =(AL39/($AG$3))*100 -> 41.13422 | AN39: =886*50/1000 -> 44.3 | AO39: =572*40/1000 -> 22.88 | AP39: =AL39/AO39*100 -> 103.55468 | AQ39: =AO39/AN39 -> 0.51647856 | AR39: =($AG$3-AN39)/$AG$3*100 -> 23.090278 | AS39: =((W39)/$AC$2) -> 0.39831556 | AT39: =((X39)/$AC$2) -> 0.20415556 | AU39: =X39/$AA$2 -> 0.19803089 | AV39: =AL39/0.75 -> 31.591081 | AW39: =Z39/$AL39*100 -> 24.529915 | AX39: =AA39/$AL39*100 -> 12.548647 | AY39: =AB39/$AL39*100 -> 0.32226817 | AZ39: =AC39/$AL39*100 -> 9.3611231 | BA39: =AD39/$AL39*100 -> 0.22304861 | BB39: =AE39/$AL39*100 -> 1.8873344 | BC39: =AF39/$AL39*100 -> 0.15785046 | BD39: =AG39/$AL39*100 -> 2.284189 | ... BH39: =AK39/$AL39*100 -> 18.878457
B40: =D40-D39 -> 1 | C40: =C39+B40 -> 50 | D40: 44790 | E40: 0.5 | G40: 64.24 | H40: 3.27 | I40: 31.41 | J40: 1.08 | Y40: =C40 -> 50
...

Sheet 1. DF_continuous_pH7_2
Q2: error
D3: C2 | E3: C3 | F3: IC4 | G3: C4 | H3: IC5 | I3: C5 | J3: IC6 | K3: C6 | L3: Lactate | M3: Succinate | N3: Formate | O3: EtOH | Q3: C2 | R3: C3 | S3: IC4 | T3: C4 | U3: IC5 | V3: C5 | W3: IC6 | X3: C6 | Y3: Lactate | Z3: Succinate | AA3: Formate | AB3: EtOH
A4: Profile | C4: OLR 30 | D4: 29.72924 | E4: 14.7718 | F4: 0.81697135 | G4: 25.480156 | H4: 0.91008856 | I4: 2.8997696 | J4: 0.21604336 | K4: 3.1234741 | L4: 4.3770613 | M4: 8.263631 | N4: 6.589855 | O4: 0 | Q4: 2.8426724 | R4: 3.2259382 | S4: 0.118519 | T4: 5.2245335 | U4: 0.095056811 | V4: 1.2318385 | W4: 0.21373819 | X4: 2.2921031 | Y4: 4.6253453 | Z4: 3.4099959 | AA4: 1.341554 | AB4: 0
C5: OLR 45 | D5: 30.708524 | E5: 13.384434 | F5: 0.7454691 | G5: 13.69062 | H5: 0.4733852 | I5: 3.4186127 | J5: 0.036656375 | K5: 3.8967982 | L5: 6.9847698 | M5: 10.868027 | N5: 7.0404088 | O5: 14 | Q5: 1.6377375 | R5: 3.8772295 | S5: 0.34917439 | T5: 4.5339548 | U5: 0.381518 | V5: 2.2670729 | W5: 0.10367989 | X5: 2.8108975 | Y5: 6.4319372 | Z5: 2.1283386 | AA5: 2.823586 | AB5: 2.23
C6: OLR 60 | D6: 26.781091 | E6: 10.106575 | F6: 0.37065305 | G6: 8.2909493 | H6: 0.1848022 | I6: 1.6168509 | J6: 0.12093959 | K6: 1.8830323 | L6: 4.0402407 | M6: 22.648206 | N6: 8.6386535 | O6: 15.32 | Q6: 2.075347 | R6: 2.3045421 | S6: 0.20934334 | T6: 1.1532528 | U6: 0.044875743 | V6: 0.29767513 | W6: 0.068046545 | X6: 0.40630587 | Y6: 3.2752762 | Z6: 2.4564627 | AA6: 1.8007032 | AB6: 2.42
P10: 2.8862545
P12: 2.8337947
P14: 4.1026949
A39: Production
E40: C2 | F40: C3 | G40: IC4 | H40: C4 | I40: IC5 | J40: C5 | K40: IC6 | L40: C6 | M40: Lactate | N40: Succinate | O40: Formate | P40: EtOH | Q40: (%) COD-met/CODin | S40: C3 | T40: IC4 | U40: C4 | V40: IC5 | W40: C5 | X40: IC6 | Y40: C6 | Z40: Lactate | AA40: Succinate | AB40: Formate | AC40: EtOH
D41: OLR 30 | E41: 5.2295804 | F41: 2.61683 | G41: 0.1439856 | H41: 4.4490096 | I41: 0.15976236 | J41: 0.50083264 | K41: 0.03916 | L41: 0.53064 | M41: 0.76844121 | N41: 1.4467834 | O41: 1.1565674 | P41: 0.51203435 | Q41: 45.7 | R41: 0.70055291 | S41: 0.67692561 | T41: 0.026482963 | U41: 0.8262059 | V41: 0.019946425 | W41: 0.18996167 | X41: 0.038653693 | Y41: 0.35536436 | Z41: 0.83891968 | AA41: 0.61607455 | AB41: 0.250252 | AC41: 1.1449436
D42: OLR 45 | E42: 7.3664346 | F42: 3.1985575 | G42: 0.17930025 | H42: 3.2794448 | I42: 0.11458783 | J42: 0.82940243 | K42: 0.00935 | L42: 0.944625 | M42: 1.6801477 | N42: 2.5915341 | O42: 1.6778144 | P42: 2.0776273 | Q42: 41.6 | R42: 0.77458645 | S42: 0.93130362 | T42: 0.089370069 | U42: 1.1236028 | V42: 0.09757652 | W42: 0.58955399 | X42: 0.026445794 | Y42: 0.71429317 | Z42: 1.6108281 | AA42: 0.49567939 | AB42: 0.6693925 | AC42: 1.7473132
D43: OLR 60 | E43: 6.5842436 | F43: 2.460092 | G43: 0.0879912 | H43: 2.0201616 | I43: 0.0447172 | J43: 0.39269832 | K43: 0.03036 | L43: 0.45716 | M43: 1.0428309 | N43: 5.5836821 | O43: 2.1125458 | P43: 3.7447 | Q43: 42.6 | R43: 0.87900157 | S43: 0.47911327 | T43: 0.041944219 | U43: 0.18954078 | V43: 0.0082564602 | W43: 0.050599086 | X43: 0.016998471 | Y43: 0.076974853 | Z43: 0.91801671 | AA43: 0.9841399 | AB43: 0.41526783 | AC43: 0.54908812

Sheet 1. DF_continuous_pH7_3
Q1: Composé | T1: Lactose | U1: Glucose | V1: Xylose | W1: Fructose | X1: Arabinose | Y1: Succinate | Z1: Lactate | AB1: Formate | AC1: Acétate | AD1: 1,3-propanediol | AE1: Propionate | AF1: isobutyrate | AG1: Ethanol | AH1: Butyrate | AI1: isovalérate | AJ1: Butanol | AK1: H2 | AL1: Caproate
Q2: gDCO/g | T2: 0.561 | U2: 1.067 | V2: 1.066 | W2: 1.067 | X2: 1.066 | Y2: 0.948 | Z2: 1.067 | AB2: 1.39 | AC2: 1.067 | AD2: 1.26 | AE2: 1.51 | AF2: 1.818 | AG2: 2.0842 | AH2: 1.818 | AI2: 2.0326 | AJ2: 2.59 | AK2: 8 | AL2: 2.2
C3: F5 -37.5C
B4: Days | C4: ='1. DF_continuous_pH7_1'!Z6 -> C2 | D4: ='1. DF_continuous_pH7_1'!AA6 -> C3 | E4: ='1. DF_continuous_pH7_1'!AB6 -> IC4 | F4: ='1. DF_continuous_pH7_1'!AC6 -> C4 | G4: ='1. DF_continuous_pH7_1'!AD6 -> IC5 | H4: ='1. DF_continuous_pH7_1'!AE6 -> C5 | I4: ='1. DF_continuous_pH7_1'!AF6 -> IC6 | J4: ='1. DF_continuous_pH7_1'!AG6 -> C6 | ... N4: ='1. DF_continuous_pH7_1'!AK6 -> EtOH | O4: (%) COD-VFAs/CODin
A5: 44741 | B5: ='1. DF_continuous_pH7_1'!Y8 -> 1 | C5: ='1. DF_continuous_pH7_1'!Z8 -> 3.87321 | D5: ='1. DF_continuous_pH7_1'!AA8 -> 5.28651 | E5: ='1. DF_continuous_pH7_1'!AB8 -> 0.079992 | F5: ='1. DF_continuous_pH7_1'!AC8 -> 1.270782 | G5: ='1. DF_continuous_pH7_1'!AD8 -> 0.0589454 | H5: ='1. DF_continuous_pH7_1'!AE8 -> 0.152445 | I5: ='1. DF_continuous_pH7_1'!AF8 -> 0 | ... N5: ='1. DF_continuous_pH7_1'!AK8 -> 0 | O5: ='1. DF_continuous_pH7_1'!AM8 -> 27.921574
A6: 44742 | B6: ='1. DF_continuous_pH7_1'!Y9 -> 2 | C6: ='1. DF_continuous_pH7_1'!Z9 -> 5.459839 | D6: ='1. DF_continuous_pH7_1'!AA9 -> 5.85578 | E6: ='1. DF_continuous_pH7_1'!AB9 -> 0.13635 | F6: ='1. DF_continuous_pH7_1'!AC9 -> 2.056158 | G6: ='1. DF_continuous_pH7_1'!AD9 -> 0.142282 | H6: ='1. DF_continuous_pH7_1'!AE9 -> 0.172771 | I6: ='1. DF_continuous_pH7_1'!AF9 -> 0.0616 | ... N6: ='1. DF_continuous_pH7_1'!AK9 -> 0 | O6: ='1. DF_continuous_pH7_1'!AM9 -> 38.20685
A7: 44743 | B7: ='1. DF_continuous_pH7_1'!Y10 -> 3 | C7: ='1. DF_continuous_pH7_1'!Z10 -> 5.730857 | D7: ='1. DF_continuous_pH7_1'!AA10 -> 4.74744 | E7: ='1. DF_continuous_pH7_1'!AB10 -> 0.156348 | F7: ='1. DF_continuous_pH7_1'!AC10 -> 2.31795 | G7: ='1. DF_continuous_pH7_1'!AD10 -> 0.162608 | H7: ='1. DF_continuous_pH7_1'!AE10 -> 0.1788688 | I7: ='1. DF_continuous_pH7_1'!AF10 -> 0.1012 | ... N7: ='1. DF_continuous_pH7_1'!AK10 -> 1.7594816 | O7: ='1. DF_continuous_pH7_1'!AM10 -> 43.101973
A8: 44746 | B8: ='1. DF_continuous_pH7_1'!Y11 -> 6 | C8: ='1. DF_continuous_pH7_1'!Z11 -> 5.600683 | D8: ='1. DF_continuous_pH7_1'!AA11 -> 3.18006 | E8: ='1. DF_continuous_pH7_1'!AB11 -> 0.141804 | F8: ='1. DF_continuous_pH7_1'!AC11 -> 2.26341 | G8: ='1. DF_continuous_pH7_1'!AD11 -> 0.1097604 | H8: ='1. DF_continuous_pH7_1'!AE11 -> 0.182934 | I8: ='1. DF_continuous_pH7_1'!AF11 -> 0.176 | ... N8: ='1. DF_continuous_pH7_1'!AK11 -> 2.5031242 | O8: ='1. DF_continuous_pH7_1'!AM11 -> 43.411489
A9: 44747 | B9: ='1. DF_continuous_pH7_1'!Y12 -> 7 | C9: ='1. DF_continuous_pH7_1'!Z12 -> 6.045622 | D9: ='1. DF_continuous_pH7_1'!AA12 -> 3.28576 | E9: ='1. DF_continuous_pH7_1'!AB12 -> 0.12726 | F9: ='1. DF_continuous_pH7_1'!AC12 -> 2.401578 | G9: ='1. DF_continuous_pH7_1'!AD12 -> 0.111793 | H9: ='1. DF_continuous_pH7_1'!AE12 -> 0.1869992 | I9: ='1. DF_continuous_pH7_1'!AF12 -> 0.1628 | ... N9: ='1. DF_continuous_pH7_1'!AK12 -> 2.490619 | O9: ='1. DF_continuous_pH7_1'!AM12 -> 44.561139
A10: 44748 | B10: ='1. DF_continuous_pH7_1'!Y13 -> 8 | C10: ='1. DF_continuous_pH7_1'!Z13 -> 5.338201 | D10: ='1. DF_continuous_pH7_1'!AA13 -> 2.79048 | E10: ='1. DF_continuous_pH7_1'!AB13 -> 0.09999 | F10: ='1. DF_continuous_pH7_1'!AC13 -> 2.685186 | G10: ='1. DF_continuous_pH7_1'!AD13 -> 0.0874018 | H10: ='1. DF_continuous_pH7_1'!AE13 -> 0.1991948 | I10: ='1. DF_continuous_pH7_1'!AF13 -> 0.1298 | ... N10: ='1. DF_continuous_pH7_1'!AK13 -> 2.9267527 | O10: ='1. DF_continuous_pH7_1'!AM13 -> 43.093716
A11: 44749 | B11: ='1. DF_continuous_pH7_1'!Y14 -> 9 | C11: ='1. DF_continuous_pH7_1'!Z14 -> 5.277382 | D11: ='1. DF_continuous_pH7_1'!AA14 -> 2.68176 | E11: ='1. DF_continuous_pH7_1'!AB14 -> 0.123624 | F11: ='1. DF_continuous_pH7_1'!AC14 -> 2.901528 | G11: ='1. DF_continuous_pH7_1'!AD14 -> 0.1239886 | H11: ='1. DF_continuous_pH7_1'!AE14 -> 0.20326 | I11: ='1. DF_continuous_pH7_1'!AF14 -> 0.1078 | ... N11: ='1. DF_continuous_pH7_1'!AK14 -> 2.5542764 | O11: ='1. DF_continuous_pH7_1'!AM14 -> 46.192448
A12: 44750 | B12: ='1. DF_continuous_pH7_1'!Y15 -> 10 | C12: ='1. DF_continuous_pH7_1'!Z15 -> 5.178151 | D12: ='1. DF_continuous_pH7_1'!AA15 -> 2.51264 | E12: ='1. DF_continuous_pH7_1'!AB15 -> 0.129078 | F12: ='1. DF_continuous_pH7_1'!AC15 -> 3.25422 | G12: ='1. DF_continuous_pH7_1'!AD15 -> 0.1382168 | H12: ='1. DF_continuous_pH7_1'!AE15 -> 0.1890318 | I12: ='1. DF_continuous_pH7_1'!AF15 -> 0.0814 | ... N12: ='1. DF_continuous_pH7_1'!AK15 -> 2.5601717 | O12: ='1. DF_continuous_pH7_1'!AM15 -> 47.252491
A13: 44753 | B13: ='1. DF_continuous_pH7_1'!Y16 -> 13 | C13: ='1. DF_continuous_pH7_1'!Z16 -> 6.234481 | D13: ='1. DF_continuous_pH7_1'!AA16 -> 3.32653 | E13: ='1. DF_continuous_pH7_1'!AB16 -> 0.176346 | F13: ='1. DF_continuous_pH7_1'!AC16 -> 4.22685 | G13: ='1. DF_continuous_pH7_1'!AD16 -> 0.162608 | H13: ='1. DF_continuous_pH7_1'!AE16 -> 0.4959544 | I13: ='1. DF_continuous_pH7_1'!AF16 -> 0.0726 | ... N13: ='1. DF_continuous_pH7_1'!AK16 -> 0 | O13: ='1. DF_continuous_pH7_1'!AM16 -> 46.850988
A14: 44754 | B14: ='1. DF_continuous_pH7_1'!Y17 -> 14 | C14: ='1. DF_continuous_pH7_1'!Z17 -> 5.393685 | D14: ='1. DF_continuous_pH7_1'!AA17 -> 3.01849 | E14: ='1. DF_continuous_pH7_1'!AB17 -> 0.161802 | F14: ='1. DF_continuous_pH7_1'!AC17 -> 4.657716 | G14: ='1. DF_continuous_pH7_1'!AD17 -> 0.1809014 | H14: ='1. DF_continuous_pH7_1'!AE17 -> 0.528476 | I14: ='1. DF_continuous_pH7_1'!AF17 -> 0.0418 | ... N14: ='1. DF_continuous_pH7_1'!AK17 -> 0 | O14: ='1. DF_continuous_pH7_1'!AM17 -> 47.728981
A15: 44755 | B15: ='1. DF_continuous_pH7_1'!Y18 -> 15 | C15: ='1. DF_continuous_pH7_1'!Z18 -> 5.05758 | D15: ='1. DF_continuous_pH7_1'!AA18 -> 2.68327 | E15: ='1. DF_continuous_pH7_1'!AB18 -> 0.143622 | F15: ='1. DF_continuous_pH7_1'!AC18 -> 5.543082 | G15: ='1. DF_continuous_pH7_1'!AD18 -> 0.1768362 | H15: ='1. DF_continuous_pH7_1'!AE18 -> 0.5975844 | I15: ='1. DF_continuous_pH7_1'!AF18 -> 0 | ... N15: ='1. DF_continuous_pH7_1'!AK18 -> 0 | O15: ='1. DF_continuous_pH7_1'!AM18 -> 46.064108
A16: 44760 | B16: ='1. DF_continuous_pH7_1'!Y19 -> 20 | C16: ='1. DF_continuous_pH7_1'!Z19 -> 4.284005 | D16: ='1. DF_continuous_pH7_1'!AA19 -> 1.54322 | E16: ='1. DF_continuous_pH7_1'!AB19 -> 0.10908 | F16: ='1. DF_continuous_pH7_1'!AC19 -> 4.56318 | G16: ='1. DF_continuous_pH7_1'!AD19 -> 0.1402494 | H16: ='1. DF_continuous_pH7_1'!AE19 -> 0.6931166 | I16: ='1. DF_continuous_pH7_1'!AF19 -> 0 | ... N16: ='1. DF_continuous_pH7_1'!AK19 -> 0 | O16: ='1. DF_continuous_pH7_1'!AM19 -> 40.666283
... A31: 44781 | B31: ='1. DF_continuous_pH7_1'!Y34 -> 41 | C31: ='1. DF_continuous_pH7_1'!Z34 -> 7.599174 | D31: ='1. DF_continuous_pH7_1'!AA34 -> 3.62098 | E31: ='1. DF_continuous_pH7_1'!AB34 -> 0.170892 | F31: ='1. DF_continuous_pH7_1'!AC34 -> 2.892438 | G31: ='1. DF_continuous_pH7_1'!AD34 -> 0.1077278 | H31: ='1. DF_continuous_pH7_1'!AE34 -> 0.7053122 | I31: ='1. DF_continuous_pH7_1'!AF34 -> 0 | ... N31: ='1. DF_continuous_pH7_1'!AK34 -> 3.1593495 | O31: ='1. DF_continuous_pH7_1'!AM34 -> 43.875456
A32: 44783 | B32: ='1. DF_continuous_pH7_1'!Y36 -> 43 | C32: ='1. DF_continuous_pH7_1'!Z36 -> 6.261156 | D32: ='1. DF_continuous_pH7_1'!AA36 -> 1.99169 | E32: ='1. DF_continuous_pH7_1'!AB36 -> 0.161802 | F32: ='1. DF_continuous_pH7_1'!AC36 -> 1.861632 | G32: ='1. DF_continuous_pH7_1'!AD36 -> 0.0447172 | H32: ='1. DF_continuous_pH7_1'!AE36 -> 0.3699332 | I32: ='1. DF_continuous_pH7_1'!AF36 -> 0 | ... N32: ='1. DF_continuous_pH7_1'!AK36 -> 3.6508038 | O32: ='1. DF_continuous_pH7_1'!AM36 -> 38.224113
A33: 44784 | B33: ='1. DF_continuous_pH7_1'!Y37 -> 44 | C33: ='1. DF_continuous_pH7_1'!Z37 -> 7.361233 | D33: ='1. DF_continuous_pH7_1'!AA37 -> 2.08984 | E33: ='1. DF_continuous_pH7_1'!AB37 -> 0.067266 | F33: ='1. DF_continuous_pH7_1'!AC37 -> 1.823454 | G33: ='1. DF_continuous_pH7_1'!AD37 -> 0.0345542 | H33: ='1. DF_continuous_pH7_1'!AE37 -> 0.3435094 | I33: ='1. DF_continuous_pH7_1'!AF37 -> 0.0374 | ... N33: ='1. DF_continuous_pH7_1'!AK37 -> 3.3056603 | O33: ='1. DF_continuous_pH7_1'!AM37 -> 44.044364
A34: 44785 | B34: ='1. DF_continuous_pH7_1'!Y38 -> 45 | C34: ='1. DF_continuous_pH7_1'!Z38 -> 7.674931 | D34: ='1. DF_continuous_pH7_1'!AA38 -> 2.27255 | E34: ='1. DF_continuous_pH7_1'!AB38 -> 0.058176 | F34: ='1. DF_continuous_pH7_1'!AC38 -> 1.979802 | G34: ='1. DF_continuous_pH7_1'!AD38 -> 0.0386194 | H34: ='1. DF_continuous_pH7_1'!AE38 -> 0.355705 | I34: ='1. DF_continuous_pH7_1'!AF38 -> 0.0396 | ... N34: ='1. DF_continuous_pH7_1'!AK38 -> 4.1240363 | O34: ='1. DF_continuous_pH7_1'!AM38 -> 48.985395
A35: 44789 | B35: ='1. DF_continuous_pH7_1'!Y39 -> 49 | C35: ='1. DF_continuous_pH7_1'!Z39 -> 5.811949 | D35: ='1. DF_continuous_pH7_1'!AA39 -> 2.97319 | E35: ='1. DF_continuous_pH7_1'!AB39 -> 0.076356 | F35: ='1. DF_continuous_pH7_1'!AC39 -> 2.21796 | G35: ='1. DF_continuous_pH7_1'!AD39 -> 0.0528476 | H35: ='1. DF_continuous_pH7_1'!AE39 -> 0.447172 | I35: ='1. DF_continuous_pH7_1'!AF39 -> 0.0374 | ... N35: ='1. DF_continuous_pH7_1'!AK39 -> 4.4729314 | O35: ='1. DF_continuous_pH7_1'!AM39 -> 41.13422
A36: 44791 | B36: ='1. DF_continuous_pH7_1'!Y41 -> 51 | C36: ='1. DF_continuous_pH7_1'!Z41 -> 5.811949 | D36: ='1. DF_continuous_pH7_1'!AA41 -> 2.97319 | E36: ='1. DF_continuous_pH7_1'!AB41 -> 0.076356 | F36: ='1. DF_continuous_pH7_1'!AC41 -> 2.21796 | G36: ='1. DF_continuous_pH7_1'!AD41 -> 0.0528476 | H36: ='1. DF_continuous_pH7_1'!AE41 -> 0.447172 | I36: ='1. DF_continuous_pH7_1'!AF41 -> 0.0374 | ... N36: ='1. DF_continuous_pH7_1'!AK41 -> 3.1700682 | O36: ='1. DF_continuous_pH7_1'!AM41 -> 40.816619

Sheet 1. DF_continuous_pH7_4
